Workbook

Sheet 使い方
B1: 使い方とルール
B3: ■ シートの役割
B4: 案件管理 | C4: 案件を1件1行で登録します。青文字＋うすい黄色の列だけ入力してください。
C5: グレー背景の列は自動計算です。緑文字は他のシートから集計した値です。
B6: 工数明細 | C6: 日々の工数を1行ずつ入れます。案件管理の「実績工数」と月次工数計画の「実績」に反映されます。
B7: 月次工数計画 | C7: どの案件に何月何人日を投入するかを入力します。下半分に工数明細からの実績が並びます。
B8: 発注・納品 | C8: 機器の発注を1明細1行で。発注日→希望納期→回答納期→入荷日→受入日 を追いかけます。
B9: 現地作業 | C9: 現地に行く日の予定と実施記録。作業日・時間・場所・作業者・状態を入れます。
B10: ダッシュボード | C10: C3に年度を入れると、クォーター別・ステータス別・担当者別・作業ステップ別、
C11: および機器の納品状況・現地作業の件数を自動集計します。
B12: マスタ | C12: 年度開始月（初期値4月）、1人日あたりの時間（初期値8h）、月次計画の開始年月、
C13: 各プルダウンの選択肢を変えられます。
B15: ■ 色のルール
B16: 青文字 | C16: 自分で入力するセル
B17: 黒文字＋グレー背景 | C17: そのシート内の数式による自動計算。編集しないでください。
B18: 緑文字＋グレー背景 | C18: 他のシートから集計している自動計算。編集しないでください。
B19: 黄色の塗り | C19: 設定値。会社のルールに合わせて変更してください（マスタシート）。
B20: うすい緑の行 | C20: サンプル行です。書き換えるか、行ごと削除してからお使いください。
B22: ■ 入力の順番（おすすめ）
B23: 1 | C23: マスタで年度開始月・1人日あたりの時間・月次計画の開始年月を決める
B24: 2 | C24: 案件管理に案件を登録する（案件IDは重複しない値にしてください）
B25: 3 | C25: 月次工数計画で、その案件に何月何人日を投入するか配分する
B26: 4 | C26: 機器があれば発注・納品に明細を登録する（金額は案件管理の機器原価に自動反映）
B27: 5 | C27: 現地作業に行く日を予定として登録しておく
B28: 6 | C28: 作業したら工数明細に工数を、現地作業の状態を「完了」に更新する
B30: ■ 自動でやってくれること
B31: クォーター判定 | C31: 「受注(予定)日」から年度とQ1〜Q4を自動判定します（年度開始月はマスタで変更可）。
B32: 金額まわり | C32: 機器原価＝発注・納品の金額合計、原価計＝原価(機器以外)＋機器原価、
C33: 粗利＝受注金額−原価計、加重金額＝受注金額×受注確度。
B34: 機器の納品状況 | C34: 発注件数・未入荷件数・最終入荷日・納品状況（機器なし/入荷待ち/受入待ち/受入完了）。
C35: 回答納期を過ぎても入荷していない明細は、納期差異が赤く表示されます。
B36: 現地作業 | C36: 予定件数・完了件数と、今日以降でいちばん近い「次回現地作業日」を表示します。
B37: 工数まわり | C37: 実績工数は工数明細から自動集計。残工数・消化率・予実判定（適正/注意/超過）も自動です。
C38: 月次工数計画では、予定工数に対して月配分が足りているか「差異」で確認できます。
B39: 進行状況 | C39: ステータスは色分け、進捗率はデータバー、失注行は打ち消し線になります。
B40: 遅延の検知 | C40: 完了予定日を過ぎて未完了の案件は「遅延日数」が赤く表示されます。
B42: ■ 行が足りなくなったら
B43: オートフィル | C43: 案件管理・発注・納品・現地作業は202行目、工数明細は302行目まで数式が入っています。
C44: 最終行を選択して右下を下へドラッグすると、数式・書式・プルダウンごと増やせます。
B45: 注意 | C45: 案件管理の行を増やしたら、月次工数計画の計画ブロック・実績ブロックの行も
...

Sheet 案件管理
A1: 案件管理表 │ 金額・クォーター・機器納品・現地作業・工数・進行状況をまとめて管理
A2: 案件ID | B2: 案件名 | C2: 顧客名 | D2: 担当者 | E2: 案件区分 | F2: 受注確度 | G2: ステータス | H2: 現在の作業ステップ | I2: 進捗率 | J2: 受注(予定)日 | K2: 着手日 | L2: 完了予定日 | M2: 完了日 | N2: 年度 | O2: クォーター | P2: 遅延日数 | Q2: 受注金額 | R2: 加重金額 | S2: 原価(機器以外) | T2: 機器原価 | U2: 原価計 | V2: 粗利 | W2: 粗利率 | X2: 発注件数 | Y2: 未入荷件数 | Z2: 最終入荷日 | AA2: 納品状況 | AB2: 現地作業(予定) | AC2: 現地作業(完了) | AD2: 次回現地作業日 | AE2: 予定工数 | AF2: 月次計画計 | AG2: 実績工数 | AH2: 残工数 | AI2: 工数消化率 | AJ2: 予実判定 | AK2: 備考
A3: P-001 | B3: 本社ネットワーク更改 | C3: 株式会社アルファ商事 | D3: 山田 太郎 | E3: 新規 | F3: 1 | G3: 進行中 | H3: 現地作業 | I3: 0.45 | J3: 46162 | K3: 46174 | L3: 46265 | N3: =IF($J3="","",YEAR($J3)-IF(MONTH($J3)<マスタ!$B$4,1,0)) -> 2026 | O3: =IF($J3="","","Q"&(INT(MOD(MONTH($J3)-マスタ!$B$4+12,12)/3)+1)) -> Q1 | P3: =IF($L3="","",IF($M3<>"",$M3-$L3,IF(TODAY()>$L3,TODAY()-$L3,0))) -> 15 | Q3: 4800000 | R3: =IF($Q3="","",$Q3*N($F3)) -> 4800000 | S3: 600000 | T3: =IF($A3="","",SUMIFS(発注・納品!$H$3:$H$202,発注・納品!$B$3:$B$202,$A3)) -> 1820000 | U3: =IF($Q3="","",N($S3)+N($T3)) -> 2420000 | V3: =IF($Q3="","",$Q3-N($U3)) -> 2380000 | W3: =IF(N($Q3)=0,"",$V3/$Q3) -> 0.49583333 | X3: =IF($A3="","",COUNTIFS(発注・納品!$B$3:$B$202,$A3)) -> 3 | Y3: =IF($A3="","",COUNTIFS(発注・納品!$B$3:$B$202,$A3,発注・納品!$M$3:$M$202,"")) -> 1 | Z3: =IF(N($X3)=0,"",IF(_xlfn.MAXIFS(発注・納品!$M$3:$M$202,発注・納品!$B$3:$B$202,$A3)=0,"",_xlfn.MAXIFS(発注・納品!$M$3:$M$202,発注・納品!$B$3:$B$202,$A3))) -> 46192 | AA3: =IF($A3="","",IF(N($X3)=0,"機器なし",IF(N($Y3)>0,"入荷待ち",IF(COUNTIFS(発注・納品!$B$3:$B$202,$A3,発注・納品!$N$3:$N$202,"")>0,"受入待ち","受入完了")))) -> 入荷待ち | AB3: =IF($A3="","",COUNTIFS(現地作業!$A$3:$A$202,$A3,現地作業!$L$3:$L$202,"予定")) -> 1 | AC3: =IF($A3="","",COUNTIFS(現地作業!$A$3:$A$202,$A3,現地作業!$L$3:$L$202,"完了")) -> 2 | AD3: =IF(N($AB3)=0,"",IF(_xlfn.MINIFS(現地作業!$C$3:$C$202,現地作業!$A$3:$A$202,$A3,現地作業!$L$3:$L$202,"予定",現地作業!$C$3:$C$202,">="&TODAY())=0,"",_xlfn.MINIFS(現地作業!$C$3:$C$202,現地作業!$A$3:$A$202,$A3,現地作業!$L$3:$L$202,"予定",現地作業!$C$3:$C$202,">="&TODAY()))) -> 46309 | AE3: 45 | AF3: =IF($A3="","",SUM(月次工数計画!$G$8:$AD$8)) -> 45 | AG3: =IF($A3="","",SUMIFS(工数明細!$G$3:$G$302,工数明細!$B$3:$B$302,$A3)) -> 2.25 | AH3: =IF($AE3="","",$AE3-N($AG3)) -> 42.75 | AI3: =IF(N($AE3)=0,"",$AG3/$AE3) -> 0.05 | AJ3: =IF(N($AE3)=0,"",IF($AG3>$AE3,"超過",IF($AG3>=$AE3*0.9,"注意","適正"))) -> 適正 | AK3: ※サンプル行です。書き換えるか、行ごと削除してお使いください。
A4: P-002 | B4: 基幹システム保守（年間） | C4: ベータ工業株式会社 | D4: 佐藤 花子 | E4: 保守・運用 | F4: 1 | G4: 完了 | H4: 完了 | I4: 1 | J4: 46122 | K4: 46127 | L4: 46203 | M4: 46201 | N4: =IF($J4="","",YEAR($J4)-IF(MONTH($J4)<マスタ!$B$4,1,0)) -> 2026 | O4: =IF($J4="","","Q"&(INT(MOD(MONTH($J4)-マスタ!$B$4+12,12)/3)+1)) -> Q1 | P4: =IF($L4="","",IF($M4<>"",$M4-$L4,IF(TODAY()>$L4,TODAY()-$L4,0))) -> -2 | Q4: 1200000 | R4: =IF($Q4="","",$Q4*N($F4)) -> 1200000 | S4: 480000 | T4: =IF($A4="","",SUMIFS(発注・納品!$H$3:$H$202,発注・納品!$B$3:$B$202,$A4)) -> 0 | U4: =IF($Q4="","",N($S4)+N($T4)) -> 480000 | V4: =IF($Q4="","",$Q4-N($U4)) -> 720000 | W4: =IF(N($Q4)=0,"",$V4/$Q4) -> 0.6 | X4: =IF($A4="","",COUNTIFS(発注・納品!$B$3:$B$202,$A4)) -> 0 | Y4: =IF($A4="","",COUNTIFS(発注・納品!$B$3:$B$202,$A4,発注・納品!$M$3:$M$202,"")) -> 0 | Z4: =IF(N($X4)=0,"",IF(_xlfn.MAXIFS(発注・納品!$M$3:$M$202,発注・納品!$B$3:$B$202,$A4)=0,"",_xlfn.MAXIFS(発注・納品!$M$3:$M$202,発注・納品!$B$3:$B$202,$A4))) | AA4: =IF($A4="","",IF(N($X4)=0,"機器なし",IF(N($Y4)>0,"入荷待ち",IF(COUNTIFS(発注・納品!$B$3:$B$202,$A4,発注・納品!$N$3:$N$202,"")>0,"受入待ち","受入完了")))) -> 機器なし | AB4: =IF($A4="","",COUNTIFS(現地作業!$A$3:$A$202,$A4,現地作業!$L$3:$L$202,"予定")) -> 0 | AC4: =IF($A4="","",COUNTIFS(現地作業!$A$3:$A$202,$A4,現地作業!$L$3:$L$202,"完了")) -> 0 | AD4: =IF(N($AB4)=0,"",IF(_xlfn.MINIFS(現地作業!$C$3:$C$202,現地作業!$A$3:$A$202,$A4,現地作業!$L$3:$L$202,"予定",現地作業!$C$3:$C$202,">="&TODAY())=0,"",_xlfn.MINIFS(現地作業!$C$3:$C$202,現地作業!$A$3:$A$202,$A4,現地作業!$L$3:$L$202,"予定",現地作業!$C$3:$C$202,">="&TODAY()))) | AE4: 12 | AF4: =IF($A4="","",SUM(月次工数計画!$G$9:$AD$9)) -> 12 | AG4: =IF($A4="","",SUMIFS(工数明細!$G$3:$G$302,工数明細!$B$3:$B$302,$A4)) -> 0.5 | AH4: =IF($AE4="","",$AE4-N($AG4)) -> 11.5 | AI4: =IF(N($AE4)=0,"",$AG4/$AE4) -> 0.041666667 | AJ4: =IF(N($AE4)=0,"",IF($AG4>$AE4,"超過",IF($AG4>=$AE4*0.9,"注意","適正"))) -> 適正 | AK4: ※サンプル行です。
A5: P-003 | B5: Webサイトリニューアル | C5: ガンマデザイン合同会社 | D5: 鈴木 一郎 | E5: 新規 | F5: 0.5 | G5: 未着手 | H5: 要件定義 | I5: 0.1 | J5: 46331 | L5: 46446 | N5: =IF($J5="","",YEAR($J5)-IF(MONTH($J5)<マスタ!$B$4,1,0)) -> 2026 | O5: =IF($J5="","","Q"&(INT(MOD(MONTH($J5)-マスタ!$B$4+12,12)/3)+1)) -> Q3 | P5: =IF($L5="","",IF($M5<>"",$M5-$L5,IF(TODAY()>$L5,TODAY()-$L5,0))) -> 0 | Q5: 3000000 | R5: =IF($Q5="","",$Q5*N($F5)) -> 1500000 | S5: 1500000 | T5: =IF($A5="","",SUMIFS(発注・納品!$H$3:$H$202,発注・納品!$B$3:$B$202,$A5)) -> 0 | U5: =IF($Q5="","",N($S5)+N($T5)) -> 1500000 | V5: =IF($Q5="","",$Q5-N($U5)) -> 1500000 | W5: =IF(N($Q5)=0,"",$V5/$Q5) -> 0.5 | X5: =IF($A5="","",COUNTIFS(発注・納品!$B$3:$B$202,$A5)) -> 0 | Y5: =IF($A5="","",COUNTIFS(発注・納品!$B$3:$B$202,$A5,発注・納品!$M$3:$M$202,"")) -> 0 | Z5: =IF(N($X5)=0,"",IF(_xlfn.MAXIFS(発注・納品!$M$3:$M$202,発注・納品!$B$3:$B$202,$A5)=0,"",_xlfn.MAXIFS(発注・納品!$M$3:$M$202,発注・納品!$B$3:$B$202,$A5))) | AA5: =IF($A5="","",IF(N($X5)=0,"機器なし",IF(N($Y5)>0,"入荷待ち",IF(COUNTIFS(発注・納品!$B$3:$B$202,$A5,発注・納品!$N$3:$N$202,"")>0,"受入待ち","受入完了")))) -> 機器なし | AB5: =IF($A5="","",COUNTIFS(現地作業!$A$3:$A$202,$A5,現地作業!$L$3:$L$202,"予定")) -> 0 | AC5: =IF($A5="","",COUNTIFS(現地作業!$A$3:$A$202,$A5,現地作業!$L$3:$L$202,"完了")) -> 0 | AD5: =IF(N($AB5)=0,"",IF(_xlfn.MINIFS(現地作業!$C$3:$C$202,現地作業!$A$3:$A$202,$A5,現地作業!$L$3:$L$202,"予定",現地作業!$C$3:$C$202,">="&TODAY())=0,"",_xlfn.MINIFS(現地作業!$C$3:$C$202,現地作業!$A$3:$A$202,$A5,現地作業!$L$3:$L$202,"予定",現地作業!$C$3:$C$202,">="&TODAY()))) | AE5: 30 | AF5: =IF($A5="","",SUM(月次工数計画!$G$10:$AD$10)) -> 30 | AG5: =IF($A5="","",SUMIFS(工数明細!$G$3:$G$302,工数明細!$B$3:$B$302,$A5)) -> 0 | AH5: =IF($AE5="","",$AE5-N($AG5)) -> 30 | AI5: =IF(N($AE5)=0,"",$AG5/$AE5) -> 0 | AJ5: =IF(N($AE5)=0,"",IF($AG5>$AE5,"超過",IF($AG5>=$AE5*0.9,"注意","適正"))) -> 適正 | AK5: ※サンプル行です。提案中のため確度50%。
N6: =IF($J6="","",YEAR($J6)-IF(MONTH($J6)<マスタ!$B$4,1,0)) | O6: =IF($J6="","","Q"&(INT(MOD(MONTH($J6)-マスタ!$B$4+12,12)/3)+1)) | P6: =IF($L6="","",IF($M6<>"",$M6-$L6,IF(TODAY()>$L6,TODAY()-$L6,0))) | R6: =IF($Q6="","",$Q6*N($F6)) | T6: =IF($A6="","",SUMIFS(発注・納品!$H$3:$H$202,発注・納品!$B$3:$B$202,$A6)) | U6: =IF($Q6="","",N($S6)+N($T6)) | V6: =IF($Q6="","",$Q6-N($U6)) | W6: =IF(N($Q6)=0,"",$V6/$Q6) | X6: =IF($A6="","",COUNTIFS(発注・納品!$B$3:$B$202,$A6)) | Y6: =IF($A6="","",COUNTIFS(発注・納品!$B$3:$B$202,$A6,発注・納品!$M$3:$M$202,"")) | Z6: =IF(N($X6)=0,"",IF(_xlfn.MAXIFS(発注・納品!$M$3:$M$202,発注・納品!$B$3:$B$202,$A6)=0,"",_xlfn.MAXIFS(発注・納品!$M$3:$M$202,発注・納品!$B$3:$B$202,$A6))) | AA6: =IF($A6="","",IF(N($X6)=0,"機器なし",IF(N($Y6)>0,"入荷待ち",IF(COUNTIFS(発注・納品!$B$3:$B$202,$A6,発注・納品!$N$3:$N$202,"")>0,"受入待ち","受入完了")))) | AB6: =IF($A6="","",COUNTIFS(現地作業!$A$3:$A$202,$A6,現地作業!$L$3:$L$202,"予定")) | AC6: =IF($A6="","",COUNTIFS(現地作業!$A$3:$A$202,$A6,現地作業!$L$3:$L$202,"完了")) | AD6: =IF(N($AB6)=0,"",IF(_xlfn.MINIFS(現地作業!$C$3:$C$202,現地作業!$A$3:$A$202,$A6,現地作業!$L$3:$L$202,"予定",現地作業!$C$3:$C$202,">="&TODAY())=0,"",_xlfn.MINIFS(現地作業!$C$3:$C$202,現地作業!$A$3:$A$202,$A6,現地作業!$L$3:$L$202,"予定",現地作業!$C$3:$C$202,">="&TODAY()))) | AF6: =IF($A6="","",SUM(月次工数計画!$G$11:$AD$11)) | AG6: =IF($A6="","",SUMIFS(工数明細!$G$3:$G$302,工数明細!$B$3:$B$302,$A6)) | AH6: =IF($AE6="","",$AE6-N($AG6)) | AI6: =IF(N($AE6)=0,"",$AG6/$AE6) | AJ6: =IF(N($AE6)=0,"",IF($AG6>$AE6,"超過",IF($AG6>=$AE6*0.9,"注意","適正")))
N7: =IF($J7="","",YEAR($J7)-IF(MONTH($J7)<マスタ!$B$4,1,0)) | O7: =IF($J7="","","Q"&(INT(MOD(MONTH($J7)-マスタ!$B$4+12,12)/3)+1)) | P7: =IF($L7="","",IF($M7<>"",$M7-$L7,IF(TODAY()>$L7,TODAY()-$L7,0))) | R7: =IF($Q7="","",$Q7*N($F7)) | T7: =IF($A7="","",SUMIFS(発注・納品!$H$3:$H$202,発注・納品!$B$3:$B$202,$A7)) | U7: =IF($Q7="","",N($S7)+N($T7)) | V7: =IF($Q7="","",$Q7-N($U7)) | W7: =IF(N($Q7)=0,"",$V7/$Q7) | X7: =IF($A7="","",COUNTIFS(発注・納品!$B$3:$B$202,$A7)) | Y7: =IF($A7="","",COUNTIFS(発注・納品!$B$3:$B$202,$A7,発注・納品!$M$3:$M$202,"")) | Z7: =IF(N($X7)=0,"",IF(_xlfn.MAXIFS(発注・納品!$M$3:$M$202,発注・納品!$B$3:$B$202,$A7)=0,"",_xlfn.MAXIFS(発注・納品!$M$3:$M$202,発注・納品!$B$3:$B$202,$A7))) | AA7: =IF($A7="","",IF(N($X7)=0,"機器なし",IF(N($Y7)>0,"入荷待ち",IF(COUNTIFS(発注・納品!$B$3:$B$202,$A7,発注・納品!$N$3:$N$202,"")>0,"受入待ち","受入完了")))) | AB7: =IF($A7="","",COUNTIFS(現地作業!$A$3:$A$202,$A7,現地作業!$L$3:$L$202,"予定")) | AC7: =IF($A7="","",COUNTIFS(現地作業!$A$3:$A$202,$A7,現地作業!$L$3:$L$202,"完了")) | AD7: =IF(N($AB7)=0,"",IF(_xlfn.MINIFS(現地作業!$C$3:$C$202,現地作業!$A$3:$A$202,$A7,現地作業!$L$3:$L$202,"予定",現地作業!$C$3:$C$202,">="&TODAY())=0,"",_xlfn.MINIFS(現地作業!$C$3:$C$202,現地作業!$A$3:$A$202,$A7,現地作業!$L$3:$L$202,"予定",現地作業!$C$3:$C$202,">="&TODAY()))) | AF7: =IF($A7="","",SUM(月次工数計画!$G$12:$AD$12)) | AG7: =IF($A7="","",SUMIFS(工数明細!$G$3:$G$302,工数明細!$B$3:$B$302,$A7)) | AH7: =IF($AE7="","",$AE7-N($AG7)) | AI7: =IF(N($AE7)=0,"",$AG7/$AE7) | AJ7: =IF(N($AE7)=0,"",IF($AG7>$AE7,"超過",IF($AG7>=$AE7*0.9,"注意","適正")))
N8: =IF($J8="","",YEAR($J8)-IF(MONTH($J8)<マスタ!$B$4,1,0)) | O8: =IF($J8="","","Q"&(INT(MOD(MONTH($J8)-マスタ!$B$4+12,12)/3)+1)) | P8: =IF($L8="","",IF($M8<>"",$M8-$L8,IF(TODAY()>$L8,TODAY()-$L8,0))) | R8: =IF($Q8="","",$Q8*N($F8)) | T8: =IF($A8="","",SUMIFS(発注・納品!$H$3:$H$202,発注・納品!$B$3:$B$202,$A8)) | U8: =IF($Q8="","",N($S8)+N($T8)) | V8: =IF($Q8="","",$Q8-N($U8)) | W8: =IF(N($Q8)=0,"",$V8/$Q8) | X8: =IF($A8="","",COUNTIFS(発注・納品!$B$3:$B$202,$A8)) | Y8: =IF($A8="","",COUNTIFS(発注・納品!$B$3:$B$202,$A8,発注・納品!$M$3:$M$202,"")) | Z8: =IF(N($X8)=0,"",IF(_xlfn.MAXIFS(発注・納品!$M$3:$M$202,発注・納品!$B$3:$B$202,$A8)=0,"",_xlfn.MAXIFS(発注・納品!$M$3:$M$202,発注・納品!$B$3:$B$202,$A8))) | AA8: =IF($A8="","",IF(N($X8)=0,"機器なし",IF(N($Y8)>0,"入荷待ち",IF(COUNTIFS(発注・納品!$B$3:$B$202,$A8,発注・納品!$N$3:$N$202,"")>0,"受入待ち","受入完了")))) | AB8: =IF($A8="","",COUNTIFS(現地作業!$A$3:$A$202,$A8,現地作業!$L$3:$L$202,"予定")) | AC8: =IF($A8="","",COUNTIFS(現地作業!$A$3:$A$202,$A8,現地作業!$L$3:$L$202,"完了")) | AD8: =IF(N($AB8)=0,"",IF(_xlfn.MINIFS(現地作業!$C$3:$C$202,現地作業!$A$3:$A$202,$A8,現地作業!$L$3:$L$202,"予定",現地作業!$C$3:$C$202,">="&TODAY())=0,"",_xlfn.MINIFS(現地作業!$C$3:$C$202,現地作業!$A$3:$A$202,$A8,現地作業!$L$3:$L$202,"予定",現地作業!$C$3:$C$202,">="&TODAY()))) | AF8: =IF($A8="","",SUM(月次工数計画!$G$13:$AD$13)) | AG8: =IF($A8="","",SUMIFS(工数明細!$G$3:$G$302,工数明細!$B$3:$B$302,$A8)) | AH8: =IF($AE8="","",$AE8-N($AG8)) | AI8: =IF(N($AE8)=0,"",$AG8/$AE8) | AJ8: =IF(N($AE8)=0,"",IF($AG8>$AE8,"超過",IF($AG8>=$AE8*0.9,"注意","適正")))
N9: =IF($J9="","",YEAR($J9)-IF(MONTH($J9)<マスタ!$B$4,1,0)) | O9: =IF($J9="","","Q"&(INT(MOD(MONTH($J9)-マスタ!$B$4+12,12)/3)+1)) | P9: =IF($L9="","",IF($M9<>"",$M9-$L9,IF(TODAY()>$L9,TODAY()-$L9,0))) | R9: =IF($Q9="","",$Q9*N($F9)) | T9: =IF($A9="","",SUMIFS(発注・納品!$H$3:$H$202,発注・納品!$B$3:$B$202,$A9)) | U9: =IF($Q9="","",N($S9)+N($T9)) | V9: =IF($Q9="","",$Q9-N($U9)) | W9: =IF(N($Q9)=0,"",$V9/$Q9) | X9: =IF($A9="","",COUNTIFS(発注・納品!$B$3:$B$202,$A9)) | Y9: =IF($A9="","",COUNTIFS(発注・納品!$B$3:$B$202,$A9,発注・納品!$M$3:$M$202,"")) | Z9: =IF(N($X9)=0,"",IF(_xlfn.MAXIFS(発注・納品!$M$3:$M$202,発注・納品!$B$3:$B$202,$A9)=0,"",_xlfn.MAXIFS(発注・納品!$M$3:$M$202,発注・納品!$B$3:$B$202,$A9))) | AA9: =IF($A9="","",IF(N($X9)=0,"機器なし",IF(N($Y9)>0,"入荷待ち",IF(COUNTIFS(発注・納品!$B$3:$B$202,$A9,発注・納品!$N$3:$N$202,"")>0,"受入待ち","受入完了")))) | AB9: =IF($A9="","",COUNTIFS(現地作業!$A$3:$A$202,$A9,現地作業!$L$3:$L$202,"予定")) | AC9: =IF($A9="","",COUNTIFS(現地作業!$A$3:$A$202,$A9,現地作業!$L$3:$L$202,"完了")) | AD9: =IF(N($AB9)=0,"",IF(_xlfn.MINIFS(現地作業!$C$3:$C$202,現地作業!$A$3:$A$202,$A9,現地作業!$L$3:$L$202,"予定",現地作業!$C$3:$C$202,">="&TODAY())=0,"",_xlfn.MINIFS(現地作業!$C$3:$C$202,現地作業!$A$3:$A$202,$A9,現地作業!$L$3:$L$202,"予定",現地作業!$C$3:$C$202,">="&TODAY()))) | AF9: =IF($A9="","",SUM(月次工数計画!$G$14:$AD$14)) | AG9: =IF($A9="","",SUMIFS(工数明細!$G$3:$G$302,工数明細!$B$3:$B$302,$A9)) | AH9: =IF($AE9="","",$AE9-N($AG9)) | AI9: =IF(N($AE9)=0,"",$AG9/$AE9) | AJ9: =IF(N($AE9)=0,"",IF($AG9>$AE9,"超過",IF($AG9>=$AE9*0.9,"注意","適正")))
N10: =IF($J10="","",YEAR($J10)-IF(MONTH($J10)<マスタ!$B$4,1,0)) | O10: =IF($J10="","","Q"&(INT(MOD(MONTH($J10)-マスタ!$B$4+12,12)/3)+1)) | P10: =IF($L10="","",IF($M10<>"",$M10-$L10,IF(TODAY()>$L10,TODAY()-$L10,0))) | R10: =IF($Q10="","",$Q10*N($F10)) | T10: =IF($A10="","",SUMIFS(発注・納品!$H$3:$H$202,発注・納品!$B$3:$B$202,$A10)) | U10: =IF($Q10="","",N($S10)+N($T10)) | V10: =IF($Q10="","",$Q10-N($U10)) | W10: =IF(N($Q10)=0,"",$V10/$Q10) | X10: =IF($A10="","",COUNTIFS(発注・納品!$B$3:$B$202,$A10)) | Y10: =IF($A10="","",COUNTIFS(発注・納品!$B$3:$B$202,$A10,発注・納品!$M$3:$M$202,"")) | Z10: =IF(N($X10)=0,"",IF(_xlfn.MAXIFS(発注・納品!$M$3:$M$202,発注・納品!$B$3:$B$202,$A10)=0,"",_xlfn.MAXIFS(発注・納品!$M$3:$M$202,発注・納品!$B$3:$B$202,$A10))) | AA10: =IF($A10="","",IF(N($X10)=0,"機器なし",IF(N($Y10)>0,"入荷待ち",IF(COUNTIFS(発注・納品!$B$3:$B$202,$A10,発注・納品!$N$3:$N$202,"")>0,"受入待ち","受入完了")))) | AB10: =IF($A10="","",COUNTIFS(現地作業!$A$3:$A$202,$A10,現地作業!$L$3:$L$202,"予定")) | AC10: =IF($A10="","",COUNTIFS(現地作業!$A$3:$A$202,$A10,現地作業!$L$3:$L$202,"完了")) | AD10: =IF(N($AB10)=0,"",IF(_xlfn.MINIFS(現地作業!$C$3:$C$202,現地作業!$A$3:$A$202,$A10,現地作業!$L$3:$L$202,"予定",現地作業!$C$3:$C$202,">="&TODAY())=0,"",_xlfn.MINIFS(現地作業!$C$3:$C$202,現地作業!$A$3:$A$202,$A10,現地作業!$L$3:$L$202,"予定",現地作業!$C$3:$C$202,">="&TODAY()))) | AF10: =IF($A10="","",SUM(月次工数計画!$G$15:$AD$15)) | AG10: =IF($A10="","",SUMIFS(工数明細!$G$3:$G$302,工数明細!$B$3:$B$302,$A10)) | AH10: =IF($AE10="","",$AE10-N($AG10)) | AI10: =IF(N($AE10)=0,"",$AG10/$AE10) | AJ10: =IF(N($AE10)=0,"",IF($AG10>$AE10,"超過",IF($AG10>=$AE10*0.9,"注意","適正")))
N11: =IF($J11="","",YEAR($J11)-IF(MONTH($J11)<マスタ!$B$4,1,0)) | O11: =IF($J11="","","Q"&(INT(MOD(MONTH($J11)-マスタ!$B$4+12,12)/3)+1)) | P11: =IF($L11="","",IF($M11<>"",$M11-$L11,IF(TODAY()>$L11,TODAY()-$L11,0))) | R11: =IF($Q11="","",$Q11*N($F11)) | T11: =IF($A11="","",SUMIFS(発注・納品!$H$3:$H$202,発注・納品!$B$3:$B$202,$A11)) | U11: =IF($Q11="","",N($S11)+N($T11)) | V11: =IF($Q11="","",$Q11-N($U11)) | W11: =IF(N($Q11)=0,"",$V11/$Q11) | X11: =IF($A11="","",COUNTIFS(発注・納品!$B$3:$B$202,$A11)) | Y11: =IF($A11="","",COUNTIFS(発注・納品!$B$3:$B$202,$A11,発注・納品!$M$3:$M$202,"")) | Z11: =IF(N($X11)=0,"",IF(_xlfn.MAXIFS(発注・納品!$M$3:$M$202,発注・納品!$B$3:$B$202,$A11)=0,"",_xlfn.MAXIFS(発注・納品!$M$3:$M$202,発注・納品!$B$3:$B$202,$A11))) | AA11: =IF($A11="","",IF(N($X11)=0,"機器なし",IF(N($Y11)>0,"入荷待ち",IF(COUNTIFS(発注・納品!$B$3:$B$202,$A11,発注・納品!$N$3:$N$202,"")>0,"受入待ち","受入完了")))) | AB11: =IF($A11="","",COUNTIFS(現地作業!$A$3:$A$202,$A11,現地作業!$L$3:$L$202,"予定")) | AC11: =IF($A11="","",COUNTIFS(現地作業!$A$3:$A$202,$A11,現地作業!$L$3:$L$202,"完了")) | AD11: =IF(N($AB11)=0,"",IF(_xlfn.MINIFS(現地作業!$C$3:$C$202,現地作業!$A$3:$A$202,$A11,現地作業!$L$3:$L$202,"予定",現地作業!$C$3:$C$202,">="&TODAY())=0,"",_xlfn.MINIFS(現地作業!$C$3:$C$202,現地作業!$A$3:$A$202,$A11,現地作業!$L$3:$L$202,"予定",現地作業!$C$3:$C$202,">="&TODAY()))) | AF11: =IF($A11="","",SUM(月次工数計画!$G$16:$AD$16)) | AG11: =IF($A11="","",SUMIFS(工数明細!$G$3:$G$302,工数明細!$B$3:$B$302,$A11)) | AH11: =IF($AE11="","",$AE11-N($AG11)) | AI11: =IF(N($AE11)=0,"",$AG11/$AE11) | AJ11: =IF(N($AE11)=0,"",IF($AG11>$AE11,"超過",IF($AG11>=$AE11*0.9,"注意","適正")))
N12: =IF($J12="","",YEAR($J12)-IF(MONTH($J12)<マスタ!$B$4,1,0)) | O12: =IF($J12="","","Q"&(INT(MOD(MONTH($J12)-マスタ!$B$4+12,12)/3)+1)) | P12: =IF($L12="","",IF($M12<>"",$M12-$L12,IF(TODAY()>$L12,TODAY()-$L12,0))) | R12: =IF($Q12="","",$Q12*N($F12)) | T12: =IF($A12="","",SUMIFS(発注・納品!$H$3:$H$202,発注・納品!$B$3:$B$202,$A12)) | U12: =IF($Q12="","",N($S12)+N($T12)) | V12: =IF($Q12="","",$Q12-N($U12)) | W12: =IF(N($Q12)=0,"",$V12/$Q12) | X12: =IF($A12="","",COUNTIFS(発注・納品!$B$3:$B$202,$A12)) | Y12: =IF($A12="","",COUNTIFS(発注・納品!$B$3:$B$202,$A12,発注・納品!$M$3:$M$202,"")) | Z12: =IF(N($X12)=0,"",IF(_xlfn.MAXIFS(発注・納品!$M$3:$M$202,発注・納品!$B$3:$B$202,$A12)=0,"",_xlfn.MAXIFS(発注・納品!$M$3:$M$202,発注・納品!$B$3:$B$202,$A12))) | AA12: =IF($A12="","",IF(N($X12)=0,"機器なし",IF(N($Y12)>0,"入荷待ち",IF(COUNTIFS(発注・納品!$B$3:$B$202,$A12,発注・納品!$N$3:$N$202,"")>0,"受入待ち","受入完了")))) | AB12: =IF($A12="","",COUNTIFS(現地作業!$A$3:$A$202,$A12,現地作業!$L$3:$L$202,"予定")) | AC12: =IF($A12="","",COUNTIFS(現地作業!$A$3:$A$202,$A12,現地作業!$L$3:$L$202,"完了")) | AD12: =IF(N($AB12)=0,"",IF(_xlfn.MINIFS(現地作業!$C$3:$C$202,現地作業!$A$3:$A$202,$A12,現地作業!$L$3:$L$202,"予定",現地作業!$C$3:$C$202,">="&TODAY())=0,"",_xlfn.MINIFS(現地作業!$C$3:$C$202,現地作業!$A$3:$A$202,$A12,現地作業!$L$3:$L$202,"予定",現地作業!$C$3:$C$202,">="&TODAY()))) | AF12: =IF($A12="","",SUM(月次工数計画!$G$17:$AD$17)) | AG12: =IF($A12="","",SUMIFS(工数明細!$G$3:$G$302,工数明細!$B$3:$B$302,$A12)) | AH12: =IF($AE12="","",$AE12-N($AG12)) | AI12: =IF(N($AE12)=0,"",$AG12/$AE12) | AJ12: =IF(N($AE12)=0,"",IF($AG12>$AE12,"超過",IF($AG12>=$AE12*0.9,"注意","適正")))
N13: =IF($J13="","",YEAR($J13)-IF(MONTH($J13)<マスタ!$B$4,1,0)) | O13: =IF($J13="","","Q"&(INT(MOD(MONTH($J13)-マスタ!$B$4+12,12)/3)+1)) | P13: =IF($L13="","",IF($M13<>"",$M13-$L13,IF(TODAY()>$L13,TODAY()-$L13,0))) | R13: =IF($Q13="","",$Q13*N($F13)) | T13: =IF($A13="","",SUMIFS(発注・納品!$H$3:$H$202,発注・納品!$B$3:$B$202,$A13)) | U13: =IF($Q13="","",N($S13)+N($T13)) | V13: =IF($Q13="","",$Q13-N($U13)) | W13: =IF(N($Q13)=0,"",$V13/$Q13) | X13: =IF($A13="","",COUNTIFS(発注・納品!$B$3:$B$202,$A13)) | Y13: =IF($A13="","",COUNTIFS(発注・納品!$B$3:$B$202,$A13,発注・納品!$M$3:$M$202,"")) | Z13: =IF(N($X13)=0,"",IF(_xlfn.MAXIFS(発注・納品!$M$3:$M$202,発注・納品!$B$3:$B$202,$A13)=0,"",_xlfn.MAXIFS(発注・納品!$M$3:$M$202,発注・納品!$B$3:$B$202,$A13))) | AA13: =IF($A13="","",IF(N($X13)=0,"機器なし",IF(N($Y13)>0,"入荷待ち",IF(COUNTIFS(発注・納品!$B$3:$B$202,$A13,発注・納品!$N$3:$N$202,"")>0,"受入待ち","受入完了")))) | AB13: =IF($A13="","",COUNTIFS(現地作業!$A$3:$A$202,$A13,現地作業!$L$3:$L$202,"予定")) | AC13: =IF($A13="","",COUNTIFS(現地作業!$A$3:$A$202,$A13,現地作業!$L$3:$L$202,"完了")) | AD13: =IF(N($AB13)=0,"",IF(_xlfn.MINIFS(現地作業!$C$3:$C$202,現地作業!$A$3:$A$202,$A13,現地作業!$L$3:$L$202,"予定",現地作業!$C$3:$C$202,">="&TODAY())=0,"",_xlfn.MINIFS(現地作業!$C$3:$C$202,現地作業!$A$3:$A$202,$A13,現地作業!$L$3:$L$202,"予定",現地作業!$C$3:$C$202,">="&TODAY()))) | AF13: =IF($A13="","",SUM(月次工数計画!$G$18:$AD$18)) | AG13: =IF($A13="","",SUMIFS(工数明細!$G$3:$G$302,工数明細!$B$3:$B$302,$A13)) | AH13: =IF($AE13="","",$AE13-N($AG13)) | AI13: =IF(N($AE13)=0,"",$AG13/$AE13) | AJ13: =IF(N($AE13)=0,"",IF($AG13>$AE13,"超過",IF($AG13>=$AE13*0.9,"注意","適正")))
N14: =IF($J14="","",YEAR($J14)-IF(MONTH($J14)<マスタ!$B$4,1,0)) | O14: =IF($J14="","","Q"&(INT(MOD(MONTH($J14)-マスタ!$B$4+12,12)/3)+1)) | P14: =IF($L14="","",IF($M14<>"",$M14-$L14,IF(TODAY()>$L14,TODAY()-$L14,0))) | R14: =IF($Q14="","",$Q14*N($F14)) | T14: =IF($A14="","",SUMIFS(発注・納品!$H$3:$H$202,発注・納品!$B$3:$B$202,$A14)) | U14: =IF($Q14="","",N($S14)+N($T14)) | V14: =IF($Q14="","",$Q14-N($U14)) | W14: =IF(N($Q14)=0,"",$V14/$Q14) | X14: =IF($A14="","",COUNTIFS(発注・納品!$B$3:$B$202,$A14)) | Y14: =IF($A14="","",COUNTIFS(発注・納品!$B$3:$B$202,$A14,発注・納品!$M$3:$M$202,"")) | Z14: =IF(N($X14)=0,"",IF(_xlfn.MAXIFS(発注・納品!$M$3:$M$202,発注・納品!$B$3:$B$202,$A14)=0,"",_xlfn.MAXIFS(発注・納品!$M$3:$M$202,発注・納品!$B$3:$B$202,$A14))) | AA14: =IF($A14="","",IF(N($X14)=0,"機器なし",IF(N($Y14)>0,"入荷待ち",IF(COUNTIFS(発注・納品!$B$3:$B$202,$A14,発注・納品!$N$3:$N$202,"")>0,"受入待ち","受入完了")))) | AB14: =IF($A14="","",COUNTIFS(現地作業!$A$3:$A$202,$A14,現地作業!$L$3:$L$202,"予定")) | AC14: =IF($A14="","",COUNTIFS(現地作業!$A$3:$A$202,$A14,現地作業!$L$3:$L$202,"完了")) | AD14: =IF(N($AB14)=0,"",IF(_xlfn.MINIFS(現地作業!$C$3:$C$202,現地作業!$A$3:$A$202,$A14,現地作業!$L$3:$L$202,"予定",現地作業!$C$3:$C$202,">="&TODAY())=0,"",_xlfn.MINIFS(現地作業!$C$3:$C$202,現地作業!$A$3:$A$202,$A14,現地作業!$L$3:$L$202,"予定",現地作業!$C$3:$C$202,">="&TODAY()))) | AF14: =IF($A14="","",SUM(月次工数計画!$G$19:$AD$19)) | AG14: =IF($A14="","",SUMIFS(工数明細!$G$3:$G$302,工数明細!$B$3:$B$302,$A14)) | AH14: =IF($AE14="","",$AE14-N($AG14)) | AI14: =IF(N($AE14)=0,"",$AG14/$AE14) | AJ14: =IF(N($AE14)=0,"",IF($AG14>$AE14,"超過",IF($AG14>=$AE14*0.9,"注意","適正")))
N15: =IF($J15="","",YEAR($J15)-IF(MONTH($J15)<マスタ!$B$4,1,0)) | O15: =IF($J15="","","Q"&(INT(MOD(MONTH($J15)-マスタ!$B$4+12,12)/3)+1)) | P15: =IF($L15="","",IF($M15<>"",$M15-$L15,IF(TODAY()>$L15,TODAY()-$L15,0))) | R15: =IF($Q15="","",$Q15*N($F15)) | T15: =IF($A15="","",SUMIFS(発注・納品!$H$3:$H$202,発注・納品!$B$3:$B$202,$A15)) | U15: =IF($Q15="","",N($S15)+N($T15)) | V15: =IF($Q15="","",$Q15-N($U15)) | W15: =IF(N($Q15)=0,"",$V15/$Q15) | X15: =IF($A15="","",COUNTIFS(発注・納品!$B$3:$B$202,$A15)) | Y15: =IF($A15="","",COUNTIFS(発注・納品!$B$3:$B$202,$A15,発注・納品!$M$3:$M$202,"")) | Z15: =IF(N($X15)=0,"",IF(_xlfn.MAXIFS(発注・納品!$M$3:$M$202,発注・納品!$B$3:$B$202,$A15)=0,"",_xlfn.MAXIFS(発注・納品!$M$3:$M$202,発注・納品!$B$3:$B$202,$A15))) | AA15: =IF($A15="","",IF(N($X15)=0,"機器なし",IF(N($Y15)>0,"入荷待ち",IF(COUNTIFS(発注・納品!$B$3:$B$202,$A15,発注・納品!$N$3:$N$202,"")>0,"受入待ち","受入完了")))) | AB15: =IF($A15="","",COUNTIFS(現地作業!$A$3:$A$202,$A15,現地作業!$L$3:$L$202,"予定")) | AC15: =IF($A15="","",COUNTIFS(現地作業!$A$3:$A$202,$A15,現地作業!$L$3:$L$202,"完了")) | AD15: =IF(N($AB15)=0,"",IF(_xlfn.MINIFS(現地作業!$C$3:$C$202,現地作業!$A$3:$A$202,$A15,現地作業!$L$3:$L$202,"予定",現地作業!$C$3:$C$202,">="&TODAY())=0,"",_xlfn.MINIFS(現地作業!$C$3:$C$202,現地作業!$A$3:$A$202,$A15,現地作業!$L$3:$L$202,"予定",現地作業!$C$3:$C$202,">="&TODAY()))) | AF15: =IF($A15="","",SUM(月次工数計画!$G$20:$AD$20)) | AG15: =IF($A15="","",SUMIFS(工数明細!$G$3:$G$302,工数明細!$B$3:$B$302,$A15)) | AH15: =IF($AE15="","",$AE15-N($AG15)) | AI15: =IF(N($AE15)=0,"",$AG15/$AE15) | AJ15: =IF(N($AE15)=0,"",IF($AG15>$AE15,"超過",IF($AG15>=$AE15*0.9,"注意","適正")))
N16: =IF($J16="","",YEAR($J16)-IF(MONTH($J16)<マスタ!$B$4,1,0)) | O16: =IF($J16="","","Q"&(INT(MOD(MONTH($J16)-マスタ!$B$4+12,12)/3)+1)) | P16: =IF($L16="","",IF($M16<>"",$M16-$L16,IF(TODAY()>$L16,TODAY()-$L16,0))) | R16: =IF($Q16="","",$Q16*N($F16)) | T16: =IF($A16="","",SUMIFS(発注・納品!$H$3:$H$202,発注・納品!$B$3:$B$202,$A16)) | U16: =IF($Q16="","",N($S16)+N($T16)) | V16: =IF($Q16="","",$Q16-N($U16)) | W16: =IF(N($Q16)=0,"",$V16/$Q16) | X16: =IF($A16="","",COUNTIFS(発注・納品!$B$3:$B$202,$A16)) | Y16: =IF($A16="","",COUNTIFS(発注・納品!$B$3:$B$202,$A16,発注・納品!$M$3:$M$202,"")) | Z16: =IF(N($X16)=0,"",IF(_xlfn.MAXIFS(発注・納品!$M$3:$M$202,発注・納品!$B$3:$B$202,$A16)=0,"",_xlfn.MAXIFS(発注・納品!$M$3:$M$202,発注・納品!$B$3:$B$202,$A16))) | AA16: =IF($A16="","",IF(N($X16)=0,"機器なし",IF(N($Y16)>0,"入荷待ち",IF(COUNTIFS(発注・納品!$B$3:$B$202,$A16,発注・納品!$N$3:$N$202,"")>0,"受入待ち","受入完了")))) | AB16: =IF($A16="","",COUNTIFS(現地作業!$A$3:$A$202,$A16,現地作業!$L$3:$L$202,"予定")) | AC16: =IF($A16="","",COUNTIFS(現地作業!$A$3:$A$202,$A16,現地作業!$L$3:$L$202,"完了")) | AD16: =IF(N($AB16)=0,"",IF(_xlfn.MINIFS(現地作業!$C$3:$C$202,現地作業!$A$3:$A$202,$A16,現地作業!$L$3:$L$202,"予定",現地作業!$C$3:$C$202,">="&TODAY())=0,"",_xlfn.MINIFS(現地作業!$C$3:$C$202,現地作業!$A$3:$A$202,$A16,現地作業!$L$3:$L$202,"予定",現地作業!$C$3:$C$202,">="&TODAY()))) | AF16: =IF($A16="","",SUM(月次工数計画!$G$21:$AD$21)) | AG16: =IF($A16="","",SUMIFS(工数明細!$G$3:$G$302,工数明細!$B$3:$B$302,$A16)) | AH16: =IF($AE16="","",$AE16-N($AG16)) | AI16: =IF(N($AE16)=0,"",$AG16/$AE16) | AJ16: =IF(N($AE16)=0,"",IF($AG16>$AE16,"超過",IF($AG16>=$AE16*0.9,"注意","適正")))
N17: =IF($J17="","",YEAR($J17)-IF(MONTH($J17)<マスタ!$B$4,1,0)) | O17: =IF($J17="","","Q"&(INT(MOD(MONTH($J17)-マスタ!$B$4+12,12)/3)+1)) | P17: =IF($L17="","",IF($M17<>"",$M17-$L17,IF(TODAY()>$L17,TODAY()-$L17,0))) | R17: =IF($Q17="","",$Q17*N($F17)) | T17: =IF($A17="","",SUMIFS(発注・納品!$H$3:$H$202,発注・納品!$B$3:$B$202,$A17)) | U17: =IF($Q17="","",N($S17)+N($T17)) | V17: =IF($Q17="","",$Q17-N($U17)) | W17: =IF(N($Q17)=0,"",$V17/$Q17) | X17: =IF($A17="","",COUNTIFS(発注・納品!$B$3:$B$202,$A17)) | Y17: =IF($A17="","",COUNTIFS(発注・納品!$B$3:$B$202,$A17,発注・納品!$M$3:$M$202,"")) | Z17: =IF(N($X17)=0,"",IF(_xlfn.MAXIFS(発注・納品!$M$3:$M$202,発注・納品!$B$3:$B$202,$A17)=0,"",_xlfn.MAXIFS(発注・納品!$M$3:$M$202,発注・納品!$B$3:$B$202,$A17))) | AA17: =IF($A17="","",IF(N($X17)=0,"機器なし",IF(N($Y17)>0,"入荷待ち",IF(COUNTIFS(発注・納品!$B$3:$B$202,$A17,発注・納品!$N$3:$N$202,"")>0,"受入待ち","受入完了")))) | AB17: =IF($A17="","",COUNTIFS(現地作業!$A$3:$A$202,$A17,現地作業!$L$3:$L$202,"予定")) | AC17: =IF($A17="","",COUNTIFS(現地作業!$A$3:$A$202,$A17,現地作業!$L$3:$L$202,"完了")) | AD17: =IF(N($AB17)=0,"",IF(_xlfn.MINIFS(現地作業!$C$3:$C$202,現地作業!$A$3:$A$202,$A17,現地作業!$L$3:$L$202,"予定",現地作業!$C$3:$C$202,">="&TODAY())=0,"",_xlfn.MINIFS(現地作業!$C$3:$C$202,現地作業!$A$3:$A$202,$A17,現地作業!$L$3:$L$202,"予定",現地作業!$C$3:$C$202,">="&TODAY()))) | AF17: =IF($A17="","",SUM(月次工数計画!$G$22:$AD$22)) | AG17: =IF($A17="","",SUMIFS(工数明細!$G$3:$G$302,工数明細!$B$3:$B$302,$A17)) | AH17: =IF($AE17="","",$AE17-N($AG17)) | AI17: =IF(N($AE17)=0,"",$AG17/$AE17) | AJ17: =IF(N($AE17)=0,"",IF($AG17>$AE17,"超過",IF($AG17>=$AE17*0.9,"注意","適正")))
N18: =IF($J18="","",YEAR($J18)-IF(MONTH($J18)<マスタ!$B$4,1,0)) | O18: =IF($J18="","","Q"&(INT(MOD(MONTH($J18)-マスタ!$B$4+12,12)/3)+1)) | P18: =IF($L18="","",IF($M18<>"",$M18-$L18,IF(TODAY()>$L18,TODAY()-$L18,0))) | R18: =IF($Q18="","",$Q18*N($F18)) | T18: =IF($A18="","",SUMIFS(発注・納品!$H$3:$H$202,発注・納品!$B$3:$B$202,$A18)) | U18: =IF($Q18="","",N($S18)+N($T18)) | V18: =IF($Q18="","",$Q18-N($U18)) | W18: =IF(N($Q18)=0,"",$V18/$Q18) | X18: =IF($A18="","",COUNTIFS(発注・納品!$B$3:$B$202,$A18)) | Y18: =IF($A18="","",COUNTIFS(発注・納品!$B$3:$B$202,$A18,発注・納品!$M$3:$M$202,"")) | Z18: =IF(N($X18)=0,"",IF(_xlfn.MAXIFS(発注・納品!$M$3:$M$202,発注・納品!$B$3:$B$202,$A18)=0,"",_xlfn.MAXIFS(発注・納品!$M$3:$M$202,発注・納品!$B$3:$B$202,$A18))) | AA18: =IF($A18="","",IF(N($X18)=0,"機器なし",IF(N($Y18)>0,"入荷待ち",IF(COUNTIFS(発注・納品!$B$3:$B$202,$A18,発注・納品!$N$3:$N$202,"")>0,"受入待ち","受入完了")))) | AB18: =IF($A18="","",COUNTIFS(現地作業!$A$3:$A$202,$A18,現地作業!$L$3:$L$202,"予定")) | AC18: =IF($A18="","",COUNTIFS(現地作業!$A$3:$A$202,$A18,現地作業!$L$3:$L$202,"完了")) | AD18: =IF(N($AB18)=0,"",IF(_xlfn.MINIFS(現地作業!$C$3:$C$202,現地作業!$A$3:$A$202,$A18,現地作業!$L$3:$L$202,"予定",現地作業!$C$3:$C$202,">="&TODAY())=0,"",_xlfn.MINIFS(現地作業!$C$3:$C$202,現地作業!$A$3:$A$202,$A18,現地作業!$L$3:$L$202,"予定",現地作業!$C$3:$C$202,">="&TODAY()))) | AF18: =IF($A18="","",SUM(月次工数計画!$G$23:$AD$23)) | AG18: =IF($A18="","",SUMIFS(工数明細!$G$3:$G$302,工数明細!$B$3:$B$302,$A18)) | AH18: =IF($AE18="","",$AE18-N($AG18)) | AI18: =IF(N($AE18)=0,"",$AG18/$AE18) | AJ18: =IF(N($AE18)=0,"",IF($AG18>$AE18,"超過",IF($AG18>=$AE18*0.9,"注意","適正")))
N19: =IF($J19="","",YEAR($J19)-IF(MONTH($J19)<マスタ!$B$4,1,0)) | O19: =IF($J19="","","Q"&(INT(MOD(MONTH($J19)-マスタ!$B$4+12,12)/3)+1)) | P19: =IF($L19="","",IF($M19<>"",$M19-$L19,IF(TODAY()>$L19,TODAY()-$L19,0))) | R19: =IF($Q19="","",$Q19*N($F19)) | T19: =IF($A19="","",SUMIFS(発注・納品!$H$3:$H$202,発注・納品!$B$3:$B$202,$A19)) | U19: =IF($Q19="","",N($S19)+N($T19)) | V19: =IF($Q19="","",$Q19-N($U19)) | W19: =IF(N($Q19)=0,"",$V19/$Q19) | X19: =IF($A19="","",COUNTIFS(発注・納品!$B$3:$B$202,$A19)) | Y19: =IF($A19="","",COUNTIFS(発注・納品!$B$3:$B$202,$A19,発注・納品!$M$3:$M$202,"")) | Z19: =IF(N($X19)=0,"",IF(_xlfn.MAXIFS(発注・納品!$M$3:$M$202,発注・納品!$B$3:$B$202,$A19)=0,"",_xlfn.MAXIFS(発注・納品!$M$3:$M$202,発注・納品!$B$3:$B$202,$A19))) | AA19: =IF($A19="","",IF(N($X19)=0,"機器なし",IF(N($Y19)>0,"入荷待ち",IF(COUNTIFS(発注・納品!$B$3:$B$202,$A19,発注・納品!$N$3:$N$202,"")>0,"受入待ち","受入完了")))) | AB19: =IF($A19="","",COUNTIFS(現地作業!$A$3:$A$202,$A19,現地作業!$L$3:$L$202,"予定")) | AC19: =IF($A19="","",COUNTIFS(現地作業!$A$3:$A$202,$A19,現地作業!$L$3:$L$202,"完了")) | AD19: =IF(N($AB19)=0,"",IF(_xlfn.MINIFS(現地作業!$C$3:$C$202,現地作業!$A$3:$A$202,$A19,現地作業!$L$3:$L$202,"予定",現地作業!$C$3:$C$202,">="&TODAY())=0,"",_xlfn.MINIFS(現地作業!$C$3:$C$202,現地作業!$A$3:$A$202,$A19,現地作業!$L$3:$L$202,"予定",現地作業!$C$3:$C$202,">="&TODAY()))) | AF19: =IF($A19="","",SUM(月次工数計画!$G$24:$AD$24)) | AG19: =IF($A19="","",SUMIFS(工数明細!$G$3:$G$302,工数明細!$B$3:$B$302,$A19)) | AH19: =IF($AE19="","",$AE19-N($AG19)) | AI19: =IF(N($AE19)=0,"",$AG19/$AE19) | AJ19: =IF(N($AE19)=0,"",IF($AG19>$AE19,"超過",IF($AG19>=$AE19*0.9,"注意","適正")))
N20: =IF($J20="","",YEAR($J20)-IF(MONTH($J20)<マスタ!$B$4,1,0)) | O20: =IF($J20="","","Q"&(INT(MOD(MONTH($J20)-マスタ!$B$4+12,12)/3)+1)) | P20: =IF($L20="","",IF($M20<>"",$M20-$L20,IF(TODAY()>$L20,TODAY()-$L20,0))) | R20: =IF($Q20="","",$Q20*N($F20)) | T20: =IF($A20="","",SUMIFS(発注・納品!$H$3:$H$202,発注・納品!$B$3:$B$202,$A20)) | U20: =IF($Q20="","",N($S20)+N($T20)) | V20: =IF($Q20="","",$Q20-N($U20)) | W20: =IF(N($Q20)=0,"",$V20/$Q20) | X20: =IF($A20="","",COUNTIFS(発注・納品!$B$3:$B$202,$A20)) | Y20: =IF($A20="","",COUNTIFS(発注・納品!$B$3:$B$202,$A20,発注・納品!$M$3:$M$202,"")) | Z20: =IF(N($X20)=0,"",IF(_xlfn.MAXIFS(発注・納品!$M$3:$M$202,発注・納品!$B$3:$B$202,$A20)=0,"",_xlfn.MAXIFS(発注・納品!$M$3:$M$202,発注・納品!$B$3:$B$202,$A20))) | AA20: =IF($A20="","",IF(N($X20)=0,"機器なし",IF(N($Y20)>0,"入荷待ち",IF(COUNTIFS(発注・納品!$B$3:$B$202,$A20,発注・納品!$N$3:$N$202,"")>0,"受入待ち","受入完了")))) | AB20: =IF($A20="","",COUNTIFS(現地作業!$A$3:$A$202,$A20,現地作業!$L$3:$L$202,"予定")) | AC20: =IF($A20="","",COUNTIFS(現地作業!$A$3:$A$202,$A20,現地作業!$L$3:$L$202,"完了")) | AD20: =IF(N($AB20)=0,"",IF(_xlfn.MINIFS(現地作業!$C$3:$C$202,現地作業!$A$3:$A$202,$A20,現地作業!$L$3:$L$202,"予定",現地作業!$C$3:$C$202,">="&TODAY())=0,"",_xlfn.MINIFS(現地作業!$C$3:$C$202,現地作業!$A$3:$A$202,$A20,現地作業!$L$3:$L$202,"予定",現地作業!$C$3:$C$202,">="&TODAY()))) | AF20: =IF($A20="","",SUM(月次工数計画!$G$25:$AD$25)) | AG20: =IF($A20="","",SUMIFS(工数明細!$G$3:$G$302,工数明細!$B$3:$B$302,$A20)) | AH20: =IF($AE20="","",$AE20-N($AG20)) | AI20: =IF(N($AE20)=0,"",$AG20/$AE20) | AJ20: =IF(N($AE20)=0,"",IF($AG20>$AE20,"超過",IF($AG20>=$AE20*0.9,"注意","適正")))
N21: =IF($J21="","",YEAR($J21)-IF(MONTH($J21)<マスタ!$B$4,1,0)) | O21: =IF($J21="","","Q"&(INT(MOD(MONTH($J21)-マスタ!$B$4+12,12)/3)+1)) | P21: =IF($L21="","",IF($M21<>"",$M21-$L21,IF(TODAY()>$L21,TODAY()-$L21,0))) | R21: =IF($Q21="","",$Q21*N($F21)) | T21: =IF($A21="","",SUMIFS(発注・納品!$H$3:$H$202,発注・納品!$B$3:$B$202,$A21)) | U21: =IF($Q21="","",N($S21)+N($T21)) | V21: =IF($Q21="","",$Q21-N($U21)) | W21: =IF(N($Q21)=0,"",$V21/$Q21) | X21: =IF($A21="","",COUNTIFS(発注・納品!$B$3:$B$202,$A21)) | Y21: =IF($A21="","",COUNTIFS(発注・納品!$B$3:$B$202,$A21,発注・納品!$M$3:$M$202,"")) | Z21: =IF(N($X21)=0,"",IF(_xlfn.MAXIFS(発注・納品!$M$3:$M$202,発注・納品!$B$3:$B$202,$A21)=0,"",_xlfn.MAXIFS(発注・納品!$M$3:$M$202,発注・納品!$B$3:$B$202,$A21))) | AA21: =IF($A21="","",IF(N($X21)=0,"機器なし",IF(N($Y21)>0,"入荷待ち",IF(COUNTIFS(発注・納品!$B$3:$B$202,$A21,発注・納品!$N$3:$N$202,"")>0,"受入待ち","受入完了")))) | AB21: =IF($A21="","",COUNTIFS(現地作業!$A$3:$A$202,$A21,現地作業!$L$3:$L$202,"予定")) | AC21: =IF($A21="","",COUNTIFS(現地作業!$A$3:$A$202,$A21,現地作業!$L$3:$L$202,"完了")) | AD21: =IF(N($AB21)=0,"",IF(_xlfn.MINIFS(現地作業!$C$3:$C$202,現地作業!$A$3:$A$202,$A21,現地作業!$L$3:$L$202,"予定",現地作業!$C$3:$C$202,">="&TODAY())=0,"",_xlfn.MINIFS(現地作業!$C$3:$C$202,現地作業!$A$3:$A$202,$A21,現地作業!$L$3:$L$202,"予定",現地作業!$C$3:$C$202,">="&TODAY()))) | AF21: =IF($A21="","",SUM(月次工数計画!$G$26:$AD$26)) | AG21: =IF($A21="","",SUMIFS(工数明細!$G$3:$G$302,工数明細!$B$3:$B$302,$A21)) | AH21: =IF($AE21="","",$AE21-N($AG21)) | AI21: =IF(N($AE21)=0,"",$AG21/$AE21) | AJ21: =IF(N($AE21)=0,"",IF($AG21>$AE21,"超過",IF($AG21>=$AE21*0.9,"注意","適正")))
N22: =IF($J22="","",YEAR($J22)-IF(MONTH($J22)<マスタ!$B$4,1,0)) | O22: =IF($J22="","","Q"&(INT(MOD(MONTH($J22)-マスタ!$B$4+12,12)/3)+1)) | P22: =IF($L22="","",IF($M22<>"",$M22-$L22,IF(TODAY()>$L22,TODAY()-$L22,0))) | R22: =IF($Q22="","",$Q22*N($F22)) | T22: =IF($A22="","",SUMIFS(発注・納品!$H$3:$H$202,発注・納品!$B$3:$B$202,$A22)) | U22: =IF($Q22="","",N($S22)+N($T22)) | V22: =IF($Q22="","",$Q22-N($U22)) | W22: =IF(N($Q22)=0,"",$V22/$Q22) | X22: =IF($A22="","",COUNTIFS(発注・納品!$B$3:$B$202,$A22)) | Y22: =IF($A22="","",COUNTIFS(発注・納品!$B$3:$B$202,$A22,発注・納品!$M$3:$M$202,"")) | Z22: =IF(N($X22)=0,"",IF(_xlfn.MAXIFS(発注・納品!$M$3:$M$202,発注・納品!$B$3:$B$202,$A22)=0,"",_xlfn.MAXIFS(発注・納品!$M$3:$M$202,発注・納品!$B$3:$B$202,$A22))) | AA22: =IF($A22="","",IF(N($X22)=0,"機器なし",IF(N($Y22)>0,"入荷待ち",IF(COUNTIFS(発注・納品!$B$3:$B$202,$A22,発注・納品!$N$3:$N$202,"")>0,"受入待ち","受入完了")))) | AB22: =IF($A22="","",COUNTIFS(現地作業!$A$3:$A$202,$A22,現地作業!$L$3:$L$202,"予定")) | AC22: =IF($A22="","",COUNTIFS(現地作業!$A$3:$A$202,$A22,現地作業!$L$3:$L$202,"完了")) | AD22: =IF(N($AB22)=0,"",IF(_xlfn.MINIFS(現地作業!$C$3:$C$202,現地作業!$A$3:$A$202,$A22,現地作業!$L$3:$L$202,"予定",現地作業!$C$3:$C$202,">="&TODAY())=0,"",_xlfn.MINIFS(現地作業!$C$3:$C$202,現地作業!$A$3:$A$202,$A22,現地作業!$L$3:$L$202,"予定",現地作業!$C$3:$C$202,">="&TODAY()))) | AF22: =IF($A22="","",SUM(月次工数計画!$G$27:$AD$27)) | AG22: =IF($A22="","",SUMIFS(工数明細!$G$3:$G$302,工数明細!$B$3:$B$302,$A22)) | AH22: =IF($AE22="","",$AE22-N($AG22)) | AI22: =IF(N($AE22)=0,"",$AG22/$AE22) | AJ22: =IF(N($AE22)=0,"",IF($AG22>$AE22,"超過",IF($AG22>=$AE22*0.9,"注意","適正")))
N23: =IF($J23="","",YEAR($J23)-IF(MONTH($J23)<マスタ!$B$4,1,0)) | O23: =IF($J23="","","Q"&(INT(MOD(MONTH($J23)-マスタ!$B$4+12,12)/3)+1)) | P23: =IF($L23="","",IF($M23<>"",$M23-$L23,IF(TODAY()>$L23,TODAY()-$L23,0))) | R23: =IF($Q23="","",$Q23*N($F23)) | T23: =IF($A23="","",SUMIFS(発注・納品!$H$3:$H$202,発注・納品!$B$3:$B$202,$A23)) | U23: =IF($Q23="","",N($S23)+N($T23)) | V23: =IF($Q23="","",$Q23-N($U23)) | W23: =IF(N($Q23)=0,"",$V23/$Q23) | X23: =IF($A23="","",COUNTIFS(発注・納品!$B$3:$B$202,$A23)) | Y23: =IF($A23="","",COUNTIFS(発注・納品!$B$3:$B$202,$A23,発注・納品!$M$3:$M$202,"")) | Z23: =IF(N($X23)=0,"",IF(_xlfn.MAXIFS(発注・納品!$M$3:$M$202,発注・納品!$B$3:$B$202,$A23)=0,"",_xlfn.MAXIFS(発注・納品!$M$3:$M$202,発注・納品!$B$3:$B$202,$A23))) | AA23: =IF($A23="","",IF(N($X23)=0,"機器なし",IF(N($Y23)>0,"入荷待ち",IF(COUNTIFS(発注・納品!$B$3:$B$202,$A23,発注・納品!$N$3:$N$202,"")>0,"受入待ち","受入完了")))) | AB23: =IF($A23="","",COUNTIFS(現地作業!$A$3:$A$202,$A23,現地作業!$L$3:$L$202,"予定")) | AC23: =IF($A23="","",COUNTIFS(現地作業!$A$3:$A$202,$A23,現地作業!$L$3:$L$202,"完了")) | AD23: =IF(N($AB23)=0,"",IF(_xlfn.MINIFS(現地作業!$C$3:$C$202,現地作業!$A$3:$A$202,$A23,現地作業!$L$3:$L$202,"予定",現地作業!$C$3:$C$202,">="&TODAY())=0,"",_xlfn.MINIFS(現地作業!$C$3:$C$202,現地作業!$A$3:$A$202,$A23,現地作業!$L$3:$L$202,"予定",現地作業!$C$3:$C$202,">="&TODAY()))) | AF23: =IF($A23="","",SUM(月次工数計画!$G$28:$AD$28)) | AG23: =IF($A23="","",SUMIFS(工数明細!$G$3:$G$302,工数明細!$B$3:$B$302,$A23)) | AH23: =IF($AE23="","",$AE23-N($AG23)) | AI23: =IF(N($AE23)=0,"",$AG23/$AE23) | AJ23: =IF(N($AE23)=0,"",IF($AG23>$AE23,"超過",IF($AG23>=$AE23*0.9,"注意","適正")))
N24: =IF($J24="","",YEAR($J24)-IF(MONTH($J24)<マスタ!$B$4,1,0)) | O24: =IF($J24="","","Q"&(INT(MOD(MONTH($J24)-マスタ!$B$4+12,12)/3)+1)) | P24: =IF($L24="","",IF($M24<>"",$M24-$L24,IF(TODAY()>$L24,TODAY()-$L24,0))) | R24: =IF($Q24="","",$Q24*N($F24)) | T24: =IF($A24="","",SUMIFS(発注・納品!$H$3:$H$202,発注・納品!$B$3:$B$202,$A24)) | U24: =IF($Q24="","",N($S24)+N($T24)) | V24: =IF($Q24="","",$Q24-N($U24)) | W24: =IF(N($Q24)=0,"",$V24/$Q24) | X24: =IF($A24="","",COUNTIFS(発注・納品!$B$3:$B$202,$A24)) | Y24: =IF($A24="","",COUNTIFS(発注・納品!$B$3:$B$202,$A24,発注・納品!$M$3:$M$202,"")) | Z24: =IF(N($X24)=0,"",IF(_xlfn.MAXIFS(発注・納品!$M$3:$M$202,発注・納品!$B$3:$B$202,$A24)=0,"",_xlfn.MAXIFS(発注・納品!$M$3:$M$202,発注・納品!$B$3:$B$202,$A24))) | AA24: =IF($A24="","",IF(N($X24)=0,"機器なし",IF(N($Y24)>0,"入荷待ち",IF(COUNTIFS(発注・納品!$B$3:$B$202,$A24,発注・納品!$N$3:$N$202,"")>0,"受入待ち","受入完了")))) | AB24: =IF($A24="","",COUNTIFS(現地作業!$A$3:$A$202,$A24,現地作業!$L$3:$L$202,"予定")) | AC24: =IF($A24="","",COUNTIFS(現地作業!$A$3:$A$202,$A24,現地作業!$L$3:$L$202,"完了")) | AD24: =IF(N($AB24)=0,"",IF(_xlfn.MINIFS(現地作業!$C$3:$C$202,現地作業!$A$3:$A$202,$A24,現地作業!$L$3:$L$202,"予定",現地作業!$C$3:$C$202,">="&TODAY())=0,"",_xlfn.MINIFS(現地作業!$C$3:$C$202,現地作業!$A$3:$A$202,$A24,現地作業!$L$3:$L$202,"予定",現地作業!$C$3:$C$202,">="&TODAY()))) | AF24: =IF($A24="","",SUM(月次工数計画!$G$29:$AD$29)) | AG24: =IF($A24="","",SUMIFS(工数明細!$G$3:$G$302,工数明細!$B$3:$B$302,$A24)) | AH24: =IF($AE24="","",$AE24-N($AG24)) | AI24: =IF(N($AE24)=0,"",$AG24/$AE24) | AJ24: =IF(N($AE24)=0,"",IF($AG24>$AE24,"超過",IF($AG24>=$AE24*0.9,"注意","適正")))
N25: =IF($J25="","",YEAR($J25)-IF(MONTH($J25)<マスタ!$B$4,1,0)) | O25: =IF($J25="","","Q"&(INT(MOD(MONTH($J25)-マスタ!$B$4+12,12)/3)+1)) | P25: =IF($L25="","",IF($M25<>"",$M25-$L25,IF(TODAY()>$L25,TODAY()-$L25,0))) | R25: =IF($Q25="","",$Q25*N($F25)) | T25: =IF($A25="","",SUMIFS(発注・納品!$H$3:$H$202,発注・納品!$B$3:$B$202,$A25)) | U25: =IF($Q25="","",N($S25)+N($T25)) | V25: =IF($Q25="","",$Q25-N($U25)) | W25: =IF(N($Q25)=0,"",$V25/$Q25) | X25: =IF($A25="","",COUNTIFS(発注・納品!$B$3:$B$202,$A25)) | Y25: =IF($A25="","",COUNTIFS(発注・納品!$B$3:$B$202,$A25,発注・納品!$M$3:$M$202,"")) | Z25: =IF(N($X25)=0,"",IF(_xlfn.MAXIFS(発注・納品!$M$3:$M$202,発注・納品!$B$3:$B$202,$A25)=0,"",_xlfn.MAXIFS(発注・納品!$M$3:$M$202,発注・納品!$B$3:$B$202,$A25))) | AA25: =IF($A25="","",IF(N($X25)=0,"機器なし",IF(N($Y25)>0,"入荷待ち",IF(COUNTIFS(発注・納品!$B$3:$B$202,$A25,発注・納品!$N$3:$N$202,"")>0,"受入待ち","受入完了")))) | AB25: =IF($A25="","",COUNTIFS(現地作業!$A$3:$A$202,$A25,現地作業!$L$3:$L$202,"予定")) | AC25: =IF($A25="","",COUNTIFS(現地作業!$A$3:$A$202,$A25,現地作業!$L$3:$L$202,"完了")) | AD25: =IF(N($AB25)=0,"",IF(_xlfn.MINIFS(現地作業!$C$3:$C$202,現地作業!$A$3:$A$202,$A25,現地作業!$L$3:$L$202,"予定",現地作業!$C$3:$C$202,">="&TODAY())=0,"",_xlfn.MINIFS(現地作業!$C$3:$C$202,現地作業!$A$3:$A$202,$A25,現地作業!$L$3:$L$202,"予定",現地作業!$C$3:$C$202,">="&TODAY()))) | AF25: =IF($A25="","",SUM(月次工数計画!$G$30:$AD$30)) | AG25: =IF($A25="","",SUMIFS(工数明細!$G$3:$G$302,工数明細!$B$3:$B$302,$A25)) | AH25: =IF($AE25="","",$AE25-N($AG25)) | AI25: =IF(N($AE25)=0,"",$AG25/$AE25) | AJ25: =IF(N($AE25)=0,"",IF($AG25>$AE25,"超過",IF($AG25>=$AE25*0.9,"注意","適正")))
N26: =IF($J26="","",YEAR($J26)-IF(MONTH($J26)<マスタ!$B$4,1,0)) | O26: =IF($J26="","","Q"&(INT(MOD(MONTH($J26)-マスタ!$B$4+12,12)/3)+1)) | P26: =IF($L26="","",IF($M26<>"",$M26-$L26,IF(TODAY()>$L26,TODAY()-$L26,0))) | R26: =IF($Q26="","",$Q26*N($F26)) | T26: =IF($A26="","",SUMIFS(発注・納品!$H$3:$H$202,発注・納品!$B$3:$B$202,$A26)) | U26: =IF($Q26="","",N($S26)+N($T26)) | V26: =IF($Q26="","",$Q26-N($U26)) | W26: =IF(N($Q26)=0,"",$V26/$Q26) | X26: =IF($A26="","",COUNTIFS(発注・納品!$B$3:$B$202,$A26)) | Y26: =IF($A26="","",COUNTIFS(発注・納品!$B$3:$B$202,$A26,発注・納品!$M$3:$M$202,"")) | Z26: =IF(N($X26)=0,"",IF(_xlfn.MAXIFS(発注・納品!$M$3:$M$202,発注・納品!$B$3:$B$202,$A26)=0,"",_xlfn.MAXIFS(発注・納品!$M$3:$M$202,発注・納品!$B$3:$B$202,$A26))) | AA26: =IF($A26="","",IF(N($X26)=0,"機器なし",IF(N($Y26)>0,"入荷待ち",IF(COUNTIFS(発注・納品!$B$3:$B$202,$A26,発注・納品!$N$3:$N$202,"")>0,"受入待ち","受入完了")))) | AB26: =IF($A26="","",COUNTIFS(現地作業!$A$3:$A$202,$A26,現地作業!$L$3:$L$202,"予定")) | AC26: =IF($A26="","",COUNTIFS(現地作業!$A$3:$A$202,$A26,現地作業!$L$3:$L$202,"完了")) | AD26: =IF(N($AB26)=0,"",IF(_xlfn.MINIFS(現地作業!$C$3:$C$202,現地作業!$A$3:$A$202,$A26,現地作業!$L$3:$L$202,"予定",現地作業!$C$3:$C$202,">="&TODAY())=0,"",_xlfn.MINIFS(現地作業!$C$3:$C$202,現地作業!$A$3:$A$202,$A26,現地作業!$L$3:$L$202,"予定",現地作業!$C$3:$C$202,">="&TODAY()))) | AF26: =IF($A26="","",SUM(月次工数計画!$G$31:$AD$31)) | AG26: =IF($A26="","",SUMIFS(工数明細!$G$3:$G$302,工数明細!$B$3:$B$302,$A26)) | AH26: =IF($AE26="","",$AE26-N($AG26)) | AI26: =IF(N($AE26)=0,"",$AG26/$AE26) | AJ26: =IF(N($AE26)=0,"",IF($AG26>$AE26,"超過",IF($AG26>=$AE26*0.9,"注意","適正")))
N27: =IF($J27="","",YEAR($J27)-IF(MONTH($J27)<マスタ!$B$4,1,0)) | O27: =IF($J27="","","Q"&(INT(MOD(MONTH($J27)-マスタ!$B$4+12,12)/3)+1)) | P27: =IF($L27="","",IF($M27<>"",$M27-$L27,IF(TODAY()>$L27,TODAY()-$L27,0))) | R27: =IF($Q27="","",$Q27*N($F27)) | T27: =IF($A27="","",SUMIFS(発注・納品!$H$3:$H$202,発注・納品!$B$3:$B$202,$A27)) | U27: =IF($Q27="","",N($S27)+N($T27)) | V27: =IF($Q27="","",$Q27-N($U27)) | W27: =IF(N($Q27)=0,"",$V27/$Q27) | X27: =IF($A27="","",COUNTIFS(発注・納品!$B$3:$B$202,$A27)) | Y27: =IF($A27="","",COUNTIFS(発注・納品!$B$3:$B$202,$A27,発注・納品!$M$3:$M$202,"")) | Z27: =IF(N($X27)=0,"",IF(_xlfn.MAXIFS(発注・納品!$M$3:$M$202,発注・納品!$B$3:$B$202,$A27)=0,"",_xlfn.MAXIFS(発注・納品!$M$3:$M$202,発注・納品!$B$3:$B$202,$A27))) | AA27: =IF($A27="","",IF(N($X27)=0,"機器なし",IF(N($Y27)>0,"入荷待ち",IF(COUNTIFS(発注・納品!$B$3:$B$202,$A27,発注・納品!$N$3:$N$202,"")>0,"受入待ち","受入完了")))) | AB27: =IF($A27="","",COUNTIFS(現地作業!$A$3:$A$202,$A27,現地作業!$L$3:$L$202,"予定")) | AC27: =IF($A27="","",COUNTIFS(現地作業!$A$3:$A$202,$A27,現地作業!$L$3:$L$202,"完了")) | AD27: =IF(N($AB27)=0,"",IF(_xlfn.MINIFS(現地作業!$C$3:$C$202,現地作業!$A$3:$A$202,$A27,現地作業!$L$3:$L$202,"予定",現地作業!$C$3:$C$202,">="&TODAY())=0,"",_xlfn.MINIFS(現地作業!$C$3:$C$202,現地作業!$A$3:$A$202,$A27,現地作業!$L$3:$L$202,"予定",現地作業!$C$3:$C$202,">="&TODAY()))) | AF27: =IF($A27="","",SUM(月次工数計画!$G$32:$AD$32)) | AG27: =IF($A27="","",SUMIFS(工数明細!$G$3:$G$302,工数明細!$B$3:$B$302,$A27)) | AH27: =IF($AE27="","",$AE27-N($AG27)) | AI27: =IF(N($AE27)=0,"",$AG27/$AE27) | AJ27: =IF(N($AE27)=0,"",IF($AG27>$AE27,"超過",IF($AG27>=$AE27*0.9,"注意","適正")))
N28: =IF($J28="","",YEAR($J28)-IF(MONTH($J28)<マスタ!$B$4,1,0)) | O28: =IF($J28="","","Q"&(INT(MOD(MONTH($J28)-マスタ!$B$4+12,12)/3)+1)) | P28: =IF($L28="","",IF($M28<>"",$M28-$L28,IF(TODAY()>$L28,TODAY()-$L28,0))) | R28: =IF($Q28="","",$Q28*N($F28)) | T28: =IF($A28="","",SUMIFS(発注・納品!$H$3:$H$202,発注・納品!$B$3:$B$202,$A28)) | U28: =IF($Q28="","",N($S28)+N($T28)) | V28: =IF($Q28="","",$Q28-N($U28)) | W28: =IF(N($Q28)=0,"",$V28/$Q28) | X28: =IF($A28="","",COUNTIFS(発注・納品!$B$3:$B$202,$A28)) | Y28: =IF($A28="","",COUNTIFS(発注・納品!$B$3:$B$202,$A28,発注・納品!$M$3:$M$202,"")) | Z28: =IF(N($X28)=0,"",IF(_xlfn.MAXIFS(発注・納品!$M$3:$M$202,発注・納品!$B$3:$B$202,$A28)=0,"",_xlfn.MAXIFS(発注・納品!$M$3:$M$202,発注・納品!$B$3:$B$202,$A28))) | AA28: =IF($A28="","",IF(N($X28)=0,"機器なし",IF(N($Y28)>0,"入荷待ち",IF(COUNTIFS(発注・納品!$B$3:$B$202,$A28,発注・納品!$N$3:$N$202,"")>0,"受入待ち","受入完了")))) | AB28: =IF($A28="","",COUNTIFS(現地作業!$A$3:$A$202,$A28,現地作業!$L$3:$L$202,"予定")) | AC28: =IF($A28="","",COUNTIFS(現地作業!$A$3:$A$202,$A28,現地作業!$L$3:$L$202,"完了")) | AD28: =IF(N($AB28)=0,"",IF(_xlfn.MINIFS(現地作業!$C$3:$C$202,現地作業!$A$3:$A$202,$A28,現地作業!$L$3:$L$202,"予定",現地作業!$C$3:$C$202,">="&TODAY())=0,"",_xlfn.MINIFS(現地作業!$C$3:$C$202,現地作業!$A$3:$A$202,$A28,現地作業!$L$3:$L$202,"予定",現地作業!$C$3:$C$202,">="&TODAY()))) | AF28: =IF($A28="","",SUM(月次工数計画!$G$33:$AD$33)) | AG28: =IF($A28="","",SUMIFS(工数明細!$G$3:$G$302,工数明細!$B$3:$B$302,$A28)) | AH28: =IF($AE28="","",$AE28-N($AG28)) | AI28: =IF(N($AE28)=0,"",$AG28/$AE28) | AJ28: =IF(N($AE28)=0,"",IF($AG28>$AE28,"超過",IF($AG28>=$AE28*0.9,"注意","適正")))
N29: =IF($J29="","",YEAR($J29)-IF(MONTH($J29)<マスタ!$B$4,1,0)) | O29: =IF($J29="","","Q"&(INT(MOD(MONTH($J29)-マスタ!$B$4+12,12)/3)+1)) | P29: =IF($L29="","",IF($M29<>"",$M29-$L29,IF(TODAY()>$L29,TODAY()-$L29,0))) | R29: =IF($Q29="","",$Q29*N($F29)) | T29: =IF($A29="","",SUMIFS(発注・納品!$H$3:$H$202,発注・納品!$B$3:$B$202,$A29)) | U29: =IF($Q29="","",N($S29)+N($T29)) | V29: =IF($Q29="","",$Q29-N($U29)) | W29: =IF(N($Q29)=0,"",$V29/$Q29) | X29: =IF($A29="","",COUNTIFS(発注・納品!$B$3:$B$202,$A29)) | Y29: =IF($A29="","",COUNTIFS(発注・納品!$B$3:$B$202,$A29,発注・納品!$M$3:$M$202,"")) | Z29: =IF(N($X29)=0,"",IF(_xlfn.MAXIFS(発注・納品!$M$3:$M$202,発注・納品!$B$3:$B$202,$A29)=0,"",_xlfn.MAXIFS(発注・納品!$M$3:$M$202,発注・納品!$B$3:$B$202,$A29))) | AA29: =IF($A29="","",IF(N($X29)=0,"機器なし",IF(N($Y29)>0,"入荷待ち",IF(COUNTIFS(発注・納品!$B$3:$B$202,$A29,発注・納品!$N$3:$N$202,"")>0,"受入待ち","受入完了")))) | AB29: =IF($A29="","",COUNTIFS(現地作業!$A$3:$A$202,$A29,現地作業!$L$3:$L$202,"予定")) | AC29: =IF($A29="","",COUNTIFS(現地作業!$A$3:$A$202,$A29,現地作業!$L$3:$L$202,"完了")) | AD29: =IF(N($AB29)=0,"",IF(_xlfn.MINIFS(現地作業!$C$3:$C$202,現地作業!$A$3:$A$202,$A29,現地作業!$L$3:$L$202,"予定",現地作業!$C$3:$C$202,">="&TODAY())=0,"",_xlfn.MINIFS(現地作業!$C$3:$C$202,現地作業!$A$3:$A$202,$A29,現地作業!$L$3:$L$202,"予定",現地作業!$C$3:$C$202,">="&TODAY()))) | AF29: =IF($A29="","",SUM(月次工数計画!$G$34:$AD$34)) | AG29: =IF($A29="","",SUMIFS(工数明細!$G$3:$G$302,工数明細!$B$3:$B$302,$A29)) | AH29: =IF($AE29="","",$AE29-N($AG29)) | AI29: =IF(N($AE29)=0,"",$AG29/$AE29) | AJ29: =IF(N($AE29)=0,"",IF($AG29>$AE29,"超過",IF($AG29>=$AE29*0.9,"注意","適正")))
N30: =IF($J30="","",YEAR($J30)-IF(MONTH($J30)<マスタ!$B$4,1,0)) | O30: =IF($J30="","","Q"&(INT(MOD(MONTH($J30)-マスタ!$B$4+12,12)/3)+1)) | P30: =IF($L30="","",IF($M30<>"",$M30-$L30,IF(TODAY()>$L30,TODAY()-$L30,0))) | R30: =IF($Q30="","",$Q30*N($F30)) | T30: =IF($A30="","",SUMIFS(発注・納品!$H$3:$H$202,発注・納品!$B$3:$B$202,$A30)) | U30: =IF($Q30="","",N($S30)+N($T30)) | V30: =IF($Q30="","",$Q30-N($U30)) | W30: =IF(N($Q30)=0,"",$V30/$Q30) | X30: =IF($A30="","",COUNTIFS(発注・納品!$B$3:$B$202,$A30)) | Y30: =IF($A30="","",COUNTIFS(発注・納品!$B$3:$B$202,$A30,発注・納品!$M$3:$M$202,"")) | Z30: =IF(N($X30)=0,"",IF(_xlfn.MAXIFS(発注・納品!$M$3:$M$202,発注・納品!$B$3:$B$202,$A30)=0,"",_xlfn.MAXIFS(発注・納品!$M$3:$M$202,発注・納品!$B$3:$B$202,$A30))) | AA30: =IF($A30="","",IF(N($X30)=0,"機器なし",IF(N($Y30)>0,"入荷待ち",IF(COUNTIFS(発注・納品!$B$3:$B$202,$A30,発注・納品!$N$3:$N$202,"")>0,"受入待ち","受入完了")))) | AB30: =IF($A30="","",COUNTIFS(現地作業!$A$3:$A$202,$A30,現地作業!$L$3:$L$202,"予定")) | AC30: =IF($A30="","",COUNTIFS(現地作業!$A$3:$A$202,$A30,現地作業!$L$3:$L$202,"完了")) | AD30: =IF(N($AB30)=0,"",IF(_xlfn.MINIFS(現地作業!$C$3:$C$202,現地作業!$A$3:$A$202,$A30,現地作業!$L$3:$L$202,"予定",現地作業!$C$3:$C$202,">="&TODAY())=0,"",_xlfn.MINIFS(現地作業!$C$3:$C$202,現地作業!$A$3:$A$202,$A30,現地作業!$L$3:$L$202,"予定",現地作業!$C$3:$C$202,">="&TODAY()))) | AF30: =IF($A30="","",SUM(月次工数計画!$G$35:$AD$35)) | AG30: =IF($A30="","",SUMIFS(工数明細!$G$3:$G$302,工数明細!$B$3:$B$302,$A30)) | AH30: =IF($AE30="","",$AE30-N($AG30)) | AI30: =IF(N($AE30)=0,"",$AG30/$AE30) | AJ30: =IF(N($AE30)=0,"",IF($AG30>$AE30,"超過",IF($AG30>=$AE30*0.9,"注意","適正")))
N31: =IF($J31="","",YEAR($J31)-IF(MONTH($J31)<マスタ!$B$4,1,0)) | O31: =IF($J31="","","Q"&(INT(MOD(MONTH($J31)-マスタ!$B$4+12,12)/3)+1)) | P31: =IF($L31="","",IF($M31<>"",$M31-$L31,IF(TODAY()>$L31,TODAY()-$L31,0))) | R31: =IF($Q31="","",$Q31*N($F31)) | T31: =IF($A31="","",SUMIFS(発注・納品!$H$3:$H$202,発注・納品!$B$3:$B$202,$A31)) | U31: =IF($Q31="","",N($S31)+N($T31)) | V31: =IF($Q31="","",$Q31-N($U31)) | W31: =IF(N($Q31)=0,"",$V31/$Q31) | X31: =IF($A31="","",COUNTIFS(発注・納品!$B$3:$B$202,$A31)) | Y31: =IF($A31="","",COUNTIFS(発注・納品!$B$3:$B$202,$A31,発注・納品!$M$3:$M$202,"")) | Z31: =IF(N($X31)=0,"",IF(_xlfn.MAXIFS(発注・納品!$M$3:$M$202,発注・納品!$B$3:$B$202,$A31)=0,"",_xlfn.MAXIFS(発注・納品!$M$3:$M$202,発注・納品!$B$3:$B$202,$A31))) | AA31: =IF($A31="","",IF(N($X31)=0,"機器なし",IF(N($Y31)>0,"入荷待ち",IF(COUNTIFS(発注・納品!$B$3:$B$202,$A31,発注・納品!$N$3:$N$202,"")>0,"受入待ち","受入完了")))) | AB31: =IF($A31="","",COUNTIFS(現地作業!$A$3:$A$202,$A31,現地作業!$L$3:$L$202,"予定")) | AC31: =IF($A31="","",COUNTIFS(現地作業!$A$3:$A$202,$A31,現地作業!$L$3:$L$202,"完了")) | AD31: =IF(N($AB31)=0,"",IF(_xlfn.MINIFS(現地作業!$C$3:$C$202,現地作業!$A$3:$A$202,$A31,現地作業!$L$3:$L$202,"予定",現地作業!$C$3:$C$202,">="&TODAY())=0,"",_xlfn.MINIFS(現地作業!$C$3:$C$202,現地作業!$A$3:$A$202,$A31,現地作業!$L$3:$L$202,"予定",現地作業!$C$3:$C$202,">="&TODAY()))) | AF31: =IF($A31="","",SUM(月次工数計画!$G$36:$AD$36)) | AG31: =IF($A31="","",SUMIFS(工数明細!$G$3:$G$302,工数明細!$B$3:$B$302,$A31)) | AH31: =IF($AE31="","",$AE31-N($AG31)) | AI31: =IF(N($AE31)=0,"",$AG31/$AE31) | AJ31: =IF(N($AE31)=0,"",IF($AG31>$AE31,"超過",IF($AG31>=$AE31*0.9,"注意","適正")))
N32: =IF($J32="","",YEAR($J32)-IF(MONTH($J32)<マスタ!$B$4,1,0)) | O32: =IF($J32="","","Q"&(INT(MOD(MONTH($J32)-マスタ!$B$4+12,12)/3)+1)) | P32: =IF($L32="","",IF($M32<>"",$M32-$L32,IF(TODAY()>$L32,TODAY()-$L32,0))) | R32: =IF($Q32="","",$Q32*N($F32)) | T32: =IF($A32="","",SUMIFS(発注・納品!$H$3:$H$202,発注・納品!$B$3:$B$202,$A32)) | U32: =IF($Q32="","",N($S32)+N($T32)) | V32: =IF($Q32="","",$Q32-N($U32)) | W32: =IF(N($Q32)=0,"",$V32/$Q32) | X32: =IF($A32="","",COUNTIFS(発注・納品!$B$3:$B$202,$A32)) | Y32: =IF($A32="","",COUNTIFS(発注・納品!$B$3:$B$202,$A32,発注・納品!$M$3:$M$202,"")) | Z32: =IF(N($X32)=0,"",IF(_xlfn.MAXIFS(発注・納品!$M$3:$M$202,発注・納品!$B$3:$B$202,$A32)=0,"",_xlfn.MAXIFS(発注・納品!$M$3:$M$202,発注・納品!$B$3:$B$202,$A32))) | AA32: =IF($A32="","",IF(N($X32)=0,"機器なし",IF(N($Y32)>0,"入荷待ち",IF(COUNTIFS(発注・納品!$B$3:$B$202,$A32,発注・納品!$N$3:$N$202,"")>0,"受入待ち","受入完了")))) | AB32: =IF($A32="","",COUNTIFS(現地作業!$A$3:$A$202,$A32,現地作業!$L$3:$L$202,"予定")) | AC32: =IF($A32="","",COUNTIFS(現地作業!$A$3:$A$202,$A32,現地作業!$L$3:$L$202,"完了")) | AD32: =IF(N($AB32)=0,"",IF(_xlfn.MINIFS(現地作業!$C$3:$C$202,現地作業!$A$3:$A$202,$A32,現地作業!$L$3:$L$202,"予定",現地作業!$C$3:$C$202,">="&TODAY())=0,"",_xlfn.MINIFS(現地作業!$C$3:$C$202,現地作業!$A$3:$A$202,$A32,現地作業!$L$3:$L$202,"予定",現地作業!$C$3:$C$202,">="&TODAY()))) | AF32: =IF($A32="","",SUM(月次工数計画!$G$37:$AD$37)) | AG32: =IF($A32="","",SUMIFS(工数明細!$G$3:$G$302,工数明細!$B$3:$B$302,$A32)) | AH32: =IF($AE32="","",$AE32-N($AG32)) | AI32: =IF(N($AE32)=0,"",$AG32/$AE32) | AJ32: =IF(N($AE32)=0,"",IF($AG32>$AE32,"超過",IF($AG32>=$AE32*0.9,"注意","適正")))
N33: =IF($J33="","",YEAR($J33)-IF(MONTH($J33)<マスタ!$B$4,1,0)) | O33: =IF($J33="","","Q"&(INT(MOD(MONTH($J33)-マスタ!$B$4+12,12)/3)+1)) | P33: =IF($L33="","",IF($M33<>"",$M33-$L33,IF(TODAY()>$L33,TODAY()-$L33,0))) | R33: =IF($Q33="","",$Q33*N($F33)) | T33: =IF($A33="","",SUMIFS(発注・納品!$H$3:$H$202,発注・納品!$B$3:$B$202,$A33)) | U33: =IF($Q33="","",N($S33)+N($T33)) | V33: =IF($Q33="","",$Q33-N($U33)) | W33: =IF(N($Q33)=0,"",$V33/$Q33) | X33: =IF($A33="","",COUNTIFS(発注・納品!$B$3:$B$202,$A33)) | Y33: =IF($A33="","",COUNTIFS(発注・納品!$B$3:$B$202,$A33,発注・納品!$M$3:$M$202,"")) | Z33: =IF(N($X33)=0,"",IF(_xlfn.MAXIFS(発注・納品!$M$3:$M$202,発注・納品!$B$3:$B$202,$A33)=0,"",_xlfn.MAXIFS(発注・納品!$M$3:$M$202,発注・納品!$B$3:$B$202,$A33))) | AA33: =IF($A33="","",IF(N($X33)=0,"機器なし",IF(N($Y33)>0,"入荷待ち",IF(COUNTIFS(発注・納品!$B$3:$B$202,$A33,発注・納品!$N$3:$N$202,"")>0,"受入待ち","受入完了")))) | AB33: =IF($A33="","",COUNTIFS(現地作業!$A$3:$A$202,$A33,現地作業!$L$3:$L$202,"予定")) | AC33: =IF($A33="","",COUNTIFS(現地作業!$A$3:$A$202,$A33,現地作業!$L$3:$L$202,"完了")) | AD33: =IF(N($AB33)=0,"",IF(_xlfn.MINIFS(現地作業!$C$3:$C$202,現地作業!$A$3:$A$202,$A33,現地作業!$L$3:$L$202,"予定",現地作業!$C$3:$C$202,">="&TODAY())=0,"",_xlfn.MINIFS(現地作業!$C$3:$C$202,現地作業!$A$3:$A$202,$A33,現地作業!$L$3:$L$202,"予定",現地作業!$C$3:$C$202,">="&TODAY()))) | AF33: =IF($A33="","",SUM(月次工数計画!$G$38:$AD$38)) | AG33: =IF($A33="","",SUMIFS(工数明細!$G$3:$G$302,工数明細!$B$3:$B$302,$A33)) | AH33: =IF($AE33="","",$AE33-N($AG33)) | AI33: =IF(N($AE33)=0,"",$AG33/$AE33) | AJ33: =IF(N($AE33)=0,"",IF($AG33>$AE33,"超過",IF($AG33>=$AE33*0.9,"注意","適正")))
N34: =IF($J34="","",YEAR($J34)-IF(MONTH($J34)<マスタ!$B$4,1,0)) | O34: =IF($J34="","","Q"&(INT(MOD(MONTH($J34)-マスタ!$B$4+12,12)/3)+1)) | P34: =IF($L34="","",IF($M34<>"",$M34-$L34,IF(TODAY()>$L34,TODAY()-$L34,0))) | R34: =IF($Q34="","",$Q34*N($F34)) | T34: =IF($A34="","",SUMIFS(発注・納品!$H$3:$H$202,発注・納品!$B$3:$B$202,$A34)) | U34: =IF($Q34="","",N($S34)+N($T34)) | V34: =IF($Q34="","",$Q34-N($U34)) | W34: =IF(N($Q34)=0,"",$V34/$Q34) | X34: =IF($A34="","",COUNTIFS(発注・納品!$B$3:$B$202,$A34)) | Y34: =IF($A34="","",COUNTIFS(発注・納品!$B$3:$B$202,$A34,発注・納品!$M$3:$M$202,"")) | Z34: =IF(N($X34)=0,"",IF(_xlfn.MAXIFS(発注・納品!$M$3:$M$202,発注・納品!$B$3:$B$202,$A34)=0,"",_xlfn.MAXIFS(発注・納品!$M$3:$M$202,発注・納品!$B$3:$B$202,$A34))) | AA34: =IF($A34="","",IF(N($X34)=0,"機器なし",IF(N($Y34)>0,"入荷待ち",IF(COUNTIFS(発注・納品!$B$3:$B$202,$A34,発注・納品!$N$3:$N$202,"")>0,"受入待ち","受入完了")))) | AB34: =IF($A34="","",COUNTIFS(現地作業!$A$3:$A$202,$A34,現地作業!$L$3:$L$202,"予定")) | AC34: =IF($A34="","",COUNTIFS(現地作業!$A$3:$A$202,$A34,現地作業!$L$3:$L$202,"完了")) | AD34: =IF(N($AB34)=0,"",IF(_xlfn.MINIFS(現地作業!$C$3:$C$202,現地作業!$A$3:$A$202,$A34,現地作業!$L$3:$L$202,"予定",現地作業!$C$3:$C$202,">="&TODAY())=0,"",_xlfn.MINIFS(現地作業!$C$3:$C$202,現地作業!$A$3:$A$202,$A34,現地作業!$L$3:$L$202,"予定",現地作業!$C$3:$C$202,">="&TODAY()))) | AF34: =IF($A34="","",SUM(月次工数計画!$G$39:$AD$39)) | AG34: =IF($A34="","",SUMIFS(工数明細!$G$3:$G$302,工数明細!$B$3:$B$302,$A34)) | AH34: =IF($AE34="","",$AE34-N($AG34)) | AI34: =IF(N($AE34)=0,"",$AG34/$AE34) | AJ34: =IF(N($AE34)=0,"",IF($AG34>$AE34,"超過",IF($AG34>=$AE34*0.9,"注意","適正")))
N35: =IF($J35="","",YEAR($J35)-IF(MONTH($J35)<マスタ!$B$4,1,0)) | O35: =IF($J35="","","Q"&(INT(MOD(MONTH($J35)-マスタ!$B$4+12,12)/3)+1)) | P35: =IF($L35="","",IF($M35<>"",$M35-$L35,IF(TODAY()>$L35,TODAY()-$L35,0))) | R35: =IF($Q35="","",$Q35*N($F35)) | T35: =IF($A35="","",SUMIFS(発注・納品!$H$3:$H$202,発注・納品!$B$3:$B$202,$A35)) | U35: =IF($Q35="","",N($S35)+N($T35)) | V35: =IF($Q35="","",$Q35-N($U35)) | W35: =IF(N($Q35)=0,"",$V35/$Q35) | X35: =IF($A35="","",COUNTIFS(発注・納品!$B$3:$B$202,$A35)) | Y35: =IF($A35="","",COUNTIFS(発注・納品!$B$3:$B$202,$A35,発注・納品!$M$3:$M$202,"")) | Z35: =IF(N($X35)=0,"",IF(_xlfn.MAXIFS(発注・納品!$M$3:$M$202,発注・納品!$B$3:$B$202,$A35)=0,"",_xlfn.MAXIFS(発注・納品!$M$3:$M$202,発注・納品!$B$3:$B$202,$A35))) | AA35: =IF($A35="","",IF(N($X35)=0,"機器なし",IF(N($Y35)>0,"入荷待ち",IF(COUNTIFS(発注・納品!$B$3:$B$202,$A35,発注・納品!$N$3:$N$202,"")>0,"受入待ち","受入完了")))) | AB35: =IF($A35="","",COUNTIFS(現地作業!$A$3:$A$202,$A35,現地作業!$L$3:$L$202,"予定")) | AC35: =IF($A35="","",COUNTIFS(現地作業!$A$3:$A$202,$A35,現地作業!$L$3:$L$202,"完了")) | AD35: =IF(N($AB35)=0,"",IF(_xlfn.MINIFS(現地作業!$C$3:$C$202,現地作業!$A$3:$A$202,$A35,現地作業!$L$3:$L$202,"予定",現地作業!$C$3:$C$202,">="&TODAY())=0,"",_xlfn.MINIFS(現地作業!$C$3:$C$202,現地作業!$A$3:$A$202,$A35,現地作業!$L$3:$L$202,"予定",現地作業!$C$3:$C$202,">="&TODAY()))) | AF35: =IF($A35="","",SUM(月次工数計画!$G$40:$AD$40)) | AG35: =IF($A35="","",SUMIFS(工数明細!$G$3:$G$302,工数明細!$B$3:$B$302,$A35)) | AH35: =IF($AE35="","",$AE35-N($AG35)) | AI35: =IF(N($AE35)=0,"",$AG35/$AE35) | AJ35: =IF(N($AE35)=0,"",IF($AG35>$AE35,"超過",IF($AG35>=$AE35*0.9,"注意","適正")))
N36: =IF($J36="","",YEAR($J36)-IF(MONTH($J36)<マスタ!$B$4,1,0)) | O36: =IF($J36="","","Q"&(INT(MOD(MONTH($J36)-マスタ!$B$4+12,12)/3)+1)) | P36: =IF($L36="","",IF($M36<>"",$M36-$L36,IF(TODAY()>$L36,TODAY()-$L36,0))) | R36: =IF($Q36="","",$Q36*N($F36)) | T36: =IF($A36="","",SUMIFS(発注・納品!$H$3:$H$202,発注・納品!$B$3:$B$202,$A36)) | U36: =IF($Q36="","",N($S36)+N($T36)) | V36: =IF($Q36="","",$Q36-N($U36)) | W36: =IF(N($Q36)=0,"",$V36/$Q36) | X36: =IF($A36="","",COUNTIFS(発注・納品!$B$3:$B$202,$A36)) | Y36: =IF($A36="","",COUNTIFS(発注・納品!$B$3:$B$202,$A36,発注・納品!$M$3:$M$202,"")) | Z36: =IF(N($X36)=0,"",IF(_xlfn.MAXIFS(発注・納品!$M$3:$M$202,発注・納品!$B$3:$B$202,$A36)=0,"",_xlfn.MAXIFS(発注・納品!$M$3:$M$202,発注・納品!$B$3:$B$202,$A36))) | AA36: =IF($A36="","",IF(N($X36)=0,"機器なし",IF(N($Y36)>0,"入荷待ち",IF(COUNTIFS(発注・納品!$B$3:$B$202,$A36,発注・納品!$N$3:$N$202,"")>0,"受入待ち","受入完了")))) | AB36: =IF($A36="","",COUNTIFS(現地作業!$A$3:$A$202,$A36,現地作業!$L$3:$L$202,"予定")) | AC36: =IF($A36="","",COUNTIFS(現地作業!$A$3:$A$202,$A36,現地作業!$L$3:$L$202,"完了")) | AD36: =IF(N($AB36)=0,"",IF(_xlfn.MINIFS(現地作業!$C$3:$C$202,現地作業!$A$3:$A$202,$A36,現地作業!$L$3:$L$202,"予定",現地作業!$C$3:$C$202,">="&TODAY())=0,"",_xlfn.MINIFS(現地作業!$C$3:$C$202,現地作業!$A$3:$A$202,$A36,現地作業!$L$3:$L$202,"予定",現地作業!$C$3:$C$202,">="&TODAY()))) | AF36: =IF($A36="","",SUM(月次工数計画!$G$41:$AD$41)) | AG36: =IF($A36="","",SUMIFS(工数明細!$G$3:$G$302,工数明細!$B$3:$B$302,$A36)) | AH36: =IF($AE36="","",$AE36-N($AG36)) | AI36: =IF(N($AE36)=0,"",$AG36/$AE36) | AJ36: =IF(N($AE36)=0,"",IF($AG36>$AE36,"超過",IF($AG36>=$AE36*0.9,"注意","適正")))
N37: =IF($J37="","",YEAR($J37)-IF(MONTH($J37)<マスタ!$B$4,1,0)) | O37: =IF($J37="","","Q"&(INT(MOD(MONTH($J37)-マスタ!$B$4+12,12)/3)+1)) | P37: =IF($L37="","",IF($M37<>"",$M37-$L37,IF(TODAY()>$L37,TODAY()-$L37,0))) | R37: =IF($Q37="","",$Q37*N($F37)) | T37: =IF($A37="","",SUMIFS(発注・納品!$H$3:$H$202,発注・納品!$B$3:$B$202,$A37)) | U37: =IF($Q37="","",N($S37)+N($T37)) | V37: =IF($Q37="","",$Q37-N($U37)) | W37: =IF(N($Q37)=0,"",$V37/$Q37) | X37: =IF($A37="","",COUNTIFS(発注・納品!$B$3:$B$202,$A37)) | Y37: =IF($A37="","",COUNTIFS(発注・納品!$B$3:$B$202,$A37,発注・納品!$M$3:$M$202,"")) | Z37: =IF(N($X37)=0,"",IF(_xlfn.MAXIFS(発注・納品!$M$3:$M$202,発注・納品!$B$3:$B$202,$A37)=0,"",_xlfn.MAXIFS(発注・納品!$M$3:$M$202,発注・納品!$B$3:$B$202,$A37))) | AA37: =IF($A37="","",IF(N($X37)=0,"機器なし",IF(N($Y37)>0,"入荷待ち",IF(COUNTIFS(発注・納品!$B$3:$B$202,$A37,発注・納品!$N$3:$N$202,"")>0,"受入待ち","受入完了")))) | AB37: =IF($A37="","",COUNTIFS(現地作業!$A$3:$A$202,$A37,現地作業!$L$3:$L$202,"予定")) | AC37: =IF($A37="","",COUNTIFS(現地作業!$A$3:$A$202,$A37,現地作業!$L$3:$L$202,"完了")) | AD37: =IF(N($AB37)=0,"",IF(_xlfn.MINIFS(現地作業!$C$3:$C$202,現地作業!$A$3:$A$202,$A37,現地作業!$L$3:$L$202,"予定",現地作業!$C$3:$C$202,">="&TODAY())=0,"",_xlfn.MINIFS(現地作業!$C$3:$C$202,現地作業!$A$3:$A$202,$A37,現地作業!$L$3:$L$202,"予定",現地作業!$C$3:$C$202,">="&TODAY()))) | AF37: =IF($A37="","",SUM(月次工数計画!$G$42:$AD$42)) | AG37: =IF($A37="","",SUMIFS(工数明細!$G$3:$G$302,工数明細!$B$3:$B$302,$A37)) | AH37: =IF($AE37="","",$AE37-N($AG37)) | AI37: =IF(N($AE37)=0,"",$AG37/$AE37) | AJ37: =IF(N($AE37)=0,"",IF($AG37>$AE37,"超過",IF($AG37>=$AE37*0.9,"注意","適正")))
N38: =IF($J38="","",YEAR($J38)-IF(MONTH($J38)<マスタ!$B$4,1,0)) | O38: =IF($J38="","","Q"&(INT(MOD(MONTH($J38)-マスタ!$B$4+12,12)/3)+1)) | P38: =IF($L38="","",IF($M38<>"",$M38-$L38,IF(TODAY()>$L38,TODAY()-$L38,0))) | R38: =IF($Q38="","",$Q38*N($F38)) | T38: =IF($A38="","",SUMIFS(発注・納品!$H$3:$H$202,発注・納品!$B$3:$B$202,$A38)) | U38: =IF($Q38="","",N($S38)+N($T38)) | V38: =IF($Q38="","",$Q38-N($U38)) | W38: =IF(N($Q38)=0,"",$V38/$Q38) | X38: =IF($A38="","",COUNTIFS(発注・納品!$B$3:$B$202,$A38)) | Y38: =IF($A38="","",COUNTIFS(発注・納品!$B$3:$B$202,$A38,発注・納品!$M$3:$M$202,"")) | Z38: =IF(N($X38)=0,"",IF(_xlfn.MAXIFS(発注・納品!$M$3:$M$202,発注・納品!$B$3:$B$202,$A38)=0,"",_xlfn.MAXIFS(発注・納品!$M$3:$M$202,発注・納品!$B$3:$B$202,$A38))) | AA38: =IF($A38="","",IF(N($X38)=0,"機器なし",IF(N($Y38)>0,"入荷待ち",IF(COUNTIFS(発注・納品!$B$3:$B$202,$A38,発注・納品!$N$3:$N$202,"")>0,"受入待ち","受入完了")))) | AB38: =IF($A38="","",COUNTIFS(現地作業!$A$3:$A$202,$A38,現地作業!$L$3:$L$202,"予定")) | AC38: =IF($A38="","",COUNTIFS(現地作業!$A$3:$A$202,$A38,現地作業!$L$3:$L$202,"完了")) | AD38: =IF(N($AB38)=0,"",IF(_xlfn.MINIFS(現地作業!$C$3:$C$202,現地作業!$A$3:$A$202,$A38,現地作業!$L$3:$L$202,"予定",現地作業!$C$3:$C$202,">="&TODAY())=0,"",_xlfn.MINIFS(現地作業!$C$3:$C$202,現地作業!$A$3:$A$202,$A38,現地作業!$L$3:$L$202,"予定",現地作業!$C$3:$C$202,">="&TODAY()))) | AF38: =IF($A38="","",SUM(月次工数計画!$G$43:$AD$43)) | AG38: =IF($A38="","",SUMIFS(工数明細!$G$3:$G$302,工数明細!$B$3:$B$302,$A38)) | AH38: =IF($AE38="","",$AE38-N($AG38)) | AI38: =IF(N($AE38)=0,"",$AG38/$AE38) | AJ38: =IF(N($AE38)=0,"",IF($AG38>$AE38,"超過",IF($AG38>=$AE38*0.9,"注意","適正")))
N39: =IF($J39="","",YEAR($J39)-IF(MONTH($J39)<マスタ!$B$4,1,0)) | O39: =IF($J39="","","Q"&(INT(MOD(MONTH($J39)-マスタ!$B$4+12,12)/3)+1)) | P39: =IF($L39="","",IF($M39<>"",$M39-$L39,IF(TODAY()>$L39,TODAY()-$L39,0))) | R39: =IF($Q39="","",$Q39*N($F39)) | T39: =IF($A39="","",SUMIFS(発注・納品!$H$3:$H$202,発注・納品!$B$3:$B$202,$A39)) | U39: =IF($Q39="","",N($S39)+N($T39)) | V39: =IF($Q39="","",$Q39-N($U39)) | W39: =IF(N($Q39)=0,"",$V39/$Q39) | X39: =IF($A39="","",COUNTIFS(発注・納品!$B$3:$B$202,$A39)) | Y39: =IF($A39="","",COUNTIFS(発注・納品!$B$3:$B$202,$A39,発注・納品!$M$3:$M$202,"")) | Z39: =IF(N($X39)=0,"",IF(_xlfn.MAXIFS(発注・納品!$M$3:$M$202,発注・納品!$B$3:$B$202,$A39)=0,"",_xlfn.MAXIFS(発注・納品!$M$3:$M$202,発注・納品!$B$3:$B$202,$A39))) | AA39: =IF($A39="","",IF(N($X39)=0,"機器なし",IF(N($Y39)>0,"入荷待ち",IF(COUNTIFS(発注・納品!$B$3:$B$202,$A39,発注・納品!$N$3:$N$202,"")>0,"受入待ち","受入完了")))) | AB39: =IF($A39="","",COUNTIFS(現地作業!$A$3:$A$202,$A39,現地作業!$L$3:$L$202,"予定")) | AC39: =IF($A39="","",COUNTIFS(現地作業!$A$3:$A$202,$A39,現地作業!$L$3:$L$202,"完了")) | AD39: =IF(N($AB39)=0,"",IF(_xlfn.MINIFS(現地作業!$C$3:$C$202,現地作業!$A$3:$A$202,$A39,現地作業!$L$3:$L$202,"予定",現地作業!$C$3:$C$202,">="&TODAY())=0,"",_xlfn.MINIFS(現地作業!$C$3:$C$202,現地作業!$A$3:$A$202,$A39,現地作業!$L$3:$L$202,"予定",現地作業!$C$3:$C$202,">="&TODAY()))) | AF39: =IF($A39="","",SUM(月次工数計画!$G$44:$AD$44)) | AG39: =IF($A39="","",SUMIFS(工数明細!$G$3:$G$302,工数明細!$B$3:$B$302,$A39)) | AH39: =IF($AE39="","",$AE39-N($AG39)) | AI39: =IF(N($AE39)=0,"",$AG39/$AE39) | AJ39: =IF(N($AE39)=0,"",IF($AG39>$AE39,"超過",IF($AG39>=$AE39*0.9,"注意","適正")))
